Workbook

Sheet Index
A1: Team | C1: Standings
A2: Anaheim Ducks | C2: Daily Standings
A3: Boston Bruins
A4: Buffalo Sabres
A5: Calgary Flames
A6: Carolina Hurricanes
A7: Chicago Blackhawks
A8: Colorado Avalanche
A9: Columbus Blue Jackets
A10: Dallas Stars
A11: Detroit Red Wings
A12: Edmonton Oilers
A13: Florida Panthers
A14: Los Angeles Kings
... A33: Winnipeg Jets

Sheet Standings_Daily
A1: October | C1: HOME
A2: Date | B2: Standings
A3: 45937 | B3: Standings
A4: 45938 | B4: Standings
A5: 45939 | B5: Standings
A6: 45941 | B6: Standings
A7: 45942 | B7: Standings
A8: 45943 | B8: Standings
A9: 45944 | B9: Standings
A10: 45945 | B10: Standings
A11: 45946 | B11: Standings
A12: 45947 | B12: Standings
A13: 45948 | B13: Standings
A14: 45949 | B14: Standings
... A26: 45961 | B26: Standings
A27: November
A28: Date | B28: Standings
A29: 45962 | B29: Standings
A30: 45963 | B30: Standings
A31: 45964 | B31: Standings
A32: 45965 | B32: Standings
A33: 45966 | B33: Standings
A34: 45967 | B34: Standings
A35: 45968 | B35: Standings
A36: 45969 | B36: Standings
A37: 45970 | B37: Standings
A38: 45971 | B38: Standings
A39: 45972 | B39: Standings
A40: 45973 | B40: Standings
... A57: 45991 | B57: Standings
A58: December
A59: Date | B59: Standings
A60: 45992 | B60: Standings
A61: 45993 | B61: Standings
A62: 45994 | B62: Standings
A63: 45995 | B63: Standings
A64: 45996 | B64: Standings
A65: 45997 | B65: Standings
A66: 45998 | B66: Standings
A67: 45999 | B67: Standings
...

Sheet Division_League
A1: NHL | B1: Eastern Conference | C1: Western Conference | D1: Eastern Atlantic | E1: Western Central
A2: Anaheim Ducks | B2: Boston Bruins | C2: Anaheim Ducks | D2: Boston Bruins | E2: Chicago Blackhawks
A3: Boston Bruins | B3: Buffalo Sabres | C3: Calgary Flames | D3: Buffalo Sabres | E3: Colorado Avalanche
A4: Buffalo Sabres | B4: Carolina Hurricanes | C4: Chicago Blackhawks | D4: Detroit Red Wings | E4: Dallas Stars
A5: Calgary Flames | B5: Columbus Blue Jackets | C5: Colorado Avalanche | D5: Florida Panthers | E5: Minnesota Wild
A6: Carolina Hurricanes | B6: Detroit Red Wings | C6: Dallas Stars | D6: Montreal Canadiens | E6: Nashville Predators
A7: Chicago Blackhawks | B7: Florida Panthers | C7: Edmonton Oilers | D7: Ottawa Senators | E7: St. Louis Blues
A8: Colorado Avalanche | B8: Montreal Canadiens | C8: Los Angeles Kings | D8: Tampa Bay Lightning | E8: Utah Mammoth
A9: Columbus Blue Jackets | B9: New Jersey Devils | C9: Minnesota Wild | D9: Toronto Maple Leafs | E9: Winnipeg Jets
A10: Dallas Stars | B10: New York Islanders | C10: Nashville Predators | D10: Eastern Metropolitan | E10: Western Pacific
A11: Detroit Red Wings | B11: New York Rangers | C11: San Jose Sharks | D11: Carolina Hurricanes | E11: Anaheim Ducks
A12: Edmonton Oilers | B12: Ottawa Senators | C12: Seattle Kraken | D12: Columbus Blue Jackets | E12: Calgary Flames
... A17: Nashville Predators | B17: Washington Capitals | C17: Winnipeg Jets | D17: Pittsburgh Penguins | E17: Vancouver Canucks
A18: New Jersey Devils | D18: Washington Capitals | E18: Vegas Golden Knights
A19: New York Islanders
A20: New York Rangers
A21: Ottawa Senators
A22: Philadelphia Flyers
A23: Pittsburgh Penguins
A24: San Jose Sharks
A25: Seattle Kraken
A26: St. Louis Blues
A27: Tampa Bay Lightning
A28: Toronto Maple Leafs
A29: Utah Mammoth
A30: Vancouver Canucks
... A33: Winnipeg Jets

Sheet Standings (10_7_25)
A1: Eastern Conference | T1: HOME
A2: Atlantic
A3: Team | B3: GP | C3: W | D3: L | E3: OTL | F3: PTS | G3: RW | H3: ROW | I3: SOW | J3: SOL | K3: Home | L3: Away | M3: Division | N3: Conference | O3: GF | P3: GA | Q3: Diff | R3: Strk | S3: L10
A4: Florida Panthers | B4: 1 | C4: 1 | D4: 0 | E4: 0 | F4: 2 | G4: 1 | H4: 1 | I4: 0 | J4: 0 | K4: 1-0-0 | L4: 0-0-0 | M4: 0-0-0 | N4: 0-0-0 | O4: 3 | P4: 2 | Q4: 1 | R4: W1 | S4: 1-0-0
A5: Boston Bruins | B5: 0 | C5: 0 | D5: 0 | E5: 0 | F5: 0 | G5: 0 | H5: 0 | I5: 0 | J5: 0 | K5: 0-0-0 | L5: 0-0-0 | M5: 0-0-0 | N5: 0-0-0 | O5: 0 | P5: 0 | Q5: 0 | R5: 0-0 | S5: 0-0-0
A6: Buffalo Sabres | B6: 0 | C6: 0 | D6: 0 | E6: 0 | F6: 0 | G6: 0 | H6: 0 | I6: 0 | J6: 0 | K6: 0-0-0 | L6: 0-0-0 | M6: 0-0-0 | N6: 0-0-0 | O6: 0 | P6: 0 | Q6: 0 | R6: 0-0 | S6: 0-0-0
A7: Detroit Red Wings | B7: 0 | C7: 0 | D7: 0 | E7: 0 | F7: 0 | G7: 0 | H7: 0 | I7: 0 | J7: 0 | K7: 0-0-0 | L7: 0-0-0 | M7: 0-0-0 | N7: 0-0-0 | O7: 0 | P7: 0 | Q7: 0 | R7: 0-0 | S7: 0-0-0
A8: Montreal Canadiens | B8: 0 | C8: 0 | D8: 0 | E8: 0 | F8: 0 | G8: 0 | H8: 0 | I8: 0 | J8: 0 | K8: 0-0-0 | L8: 0-0-0 | M8: 0-0-0 | N8: 0-0-0 | O8: 0 | P8: 0 | Q8: 0 | R8: 0-0 | S8: 0-0-0
A9: Ottawa Senators | B9: 0 | C9: 0 | D9: 0 | E9: 0 | F9: 0 | G9: 0 | H9: 0 | I9: 0 | J9: 0 | K9: 0-0-0 | L9: 0-0-0 | M9: 0-0-0 | N9: 0-0-0 | O9: 0 | P9: 0 | Q9: 0 | R9: 0-0 | S9: 0-0-0
A10: Tampa Bay Lightning | B10: 0 | C10: 0 | D10: 0 | E10: 0 | F10: 0 | G10: 0 | H10: 0 | I10: 0 | J10: 0 | K10: 0-0-0 | L10: 0-0-0 | M10: 0-0-0 | N10: 0-0-0 | O10: 0 | P10: 0 | Q10: 0 | R10: 0-0 | S10: 0-0-0
A11: Toronto Maple Leafs | B11: 0 | C11: 0 | D11: 0 | E11: 0 | F11: 0 | G11: 0 | H11: 0 | I11: 0 | J11: 0 | K11: 0-0-0 | L11: 0-0-0 | M11: 0-0-0 | N11: 0-0-0 | O11: 0 | P11: 0 | Q11: 0 | R11: 0-0 | S11: 0-0-0
A12: Metropolitan
A13: Team | B13: GP | C13: W | D13: L | E13: OTL | F13: PTS | G13: RW | H13: ROW | I13: SOW | J13: SOL | K13: Home | L13: Away | M13: Division | N13: Conference | O13: GF | P13: GA | Q13: Diff | R13: Strk | S13: L10
A14: Pittsburgh Penguins | B14: 1 | C14: 1 | D14: 0 | E14: 0 | F14: 2 | G14: 1 | H14: 1 | I14: 0 | J14: 0 | K14: 0-0-0 | L14: 1-0-0 | M14: 1-0-0 | N14: 1-0-0 | O14: 3 | P14: 0 | Q14: 3 | R14: W1 | S14: 1-0-0
A15: Carolina Hurricanes | B15: 0 | C15: 0 | D15: 0 | E15: 0 | F15: 0 | G15: 0 | H15: 0 | I15: 0 | J15: 0 | K15: 0-0-0 | L15: 0-0-0 | M15: 0-0-0 | N15: 0-0-0 | O15: 0 | P15: 0 | Q15: 0 | R15: 0-0 | S15: 0-0-0
A16: Columbus Blue Jackets | B16: 0 | C16: 0 | D16: 0 | E16: 0 | F16: 0 | G16: 0 | H16: 0 | I16: 0 | J16: 0 | K16: 0-0-0 | L16: 0-0-0 | M16: 0-0-0 | N16: 0-0-0 | O16: 0 | P16: 0 | Q16: 0 | R16: 0-0 | S16: 0-0-0
A17: New Jersey Devils | B17: 0 | C17: 0 | D17: 0 | E17: 0 | F17: 0 | G17: 0 | H17: 0 | I17: 0 | J17: 0 | K17: 0-0-0 | L17: 0-0-0 | M17: 0-0-0 | N17: 0-0-0 | O17: 0 | P17: 0 | Q17: 0 | R17: 0-0 | S17: 0-0-0
A18: New York Islanders | B18: 0 | C18: 0 | D18: 0 | E18: 0 | F18: 0 | G18: 0 | H18: 0 | I18: 0 | J18: 0 | K18: 0-0-0 | L18: 0-0-0 | M18: 0-0-0 | N18: 0-0-0 | O18: 0 | P18: 0 | Q18: 0 | R18: 0-0 | S18: 0-0-0
A19: New York Rangers | B19: 1 | C19: 0 | D19: 1 | E19: 0 | F19: 0 | G19: 0 | H19: 0 | I19: 0 | J19: 0 | K19: 0-1-0 | L19: 0-0-0 | M19: 0-1-0 | N19: 0-1-0 | O19: 0 | P19: 3 | Q19: -3 | R19: L1 | S19: 0-1-0
A20: Philadelphia Flyers | B20: 0 | C20: 0 | D20: 0 | E20: 0 | F20: 0 | G20: 0 | H20: 0 | I20: 0 | J20: 0 | K20: 0-0-0 | L20: 0-0-0 | M20: 0-0-0 | N20: 0-0-0 | O20: 0 | P20: 0 | Q20: 0 | R20: 0-0 | S20: 0-0-0
A21: Washington Capitals | B21: 0 | C21: 0 | D21: 0 | E21: 0 | F21: 0 | G21: 0 | H21: 0 | I21: 0 | J21: 0 | K21: 0-0-0 | L21: 0-0-0 | M21: 0-0-0 | N21: 0-0-0 | O21: 0 | P21: 0 | Q21: 0 | R21: 0-0 | S21: 0-0-0
A22: Western_Conference
A23: Central
A24: Team | B24: GP | C24: W | D24: L | E24: OTL | F24: PTS | G24: RW | H24: ROW | I24: SOW | J24: SOL | K24: Home | L24: Away | M24: Division | N24: Conference | O24: GF | P24: GA | Q24: Diff | R24: Strk | S24: L10
A25: Colorado Avalanche | B25: 1 | C25: 1 | D25: 0 | E25: 0 | F25: 2 | G25: 1 | H25: 1 | I25: 0 | J25: 0 | K25: 0-0-0 | L25: 1-0-0 | M25: 0-0-0 | N25: 1-0-0 | O25: 4 | P25: 1 | Q25: 3 | R25: W1 | S25: 1-0-0
A26: Chicago Blackhawks | B26: 1 | C26: 0 | D26: 1 | E26: 0 | F26: 0 | G26: 0 | H26: 0 | I26: 0 | J26: 0 | K26: 0-0-0 | L26: 0-1-0 | M26: 0-0-0 | N26: 0-0-0 | O26: 2 | P26: 3 | Q26: -1 | R26: L1 | S26: 0-1-0
A27: Dallas Stars | B27: 0 | C27: 0 | D27: 0 | E27: 0 | F27: 0 | G27: 0 | H27: 0 | I27: 0 | J27: 0 | K27: 0-0-0 | L27: 0-0-0 | M27: 0-0-0 | N27: 0-0-0 | O27: 0 | P27: 0 | Q27: 0 | R27: 0-0 | S27: 0-0-0
A28: Minnesota Wild | B28: 0 | C28: 0 | D28: 0 | E28: 0 | F28: 0 | G28: 0 | H28: 0 | I28: 0 | J28: 0 | K28: 0-0-0 | L28: 0-0-0 | M28: 0-0-0 | N28: 0-0-0 | O28: 0 | P28: 0 | Q28: 0 | R28: 0-0 | S28: 0-0-0
A29: Nashville Predators | B29: 0 | C29: 0 | D29: 0 | E29: 0 | F29: 0 | G29: 0 | H29: 0 | I29: 0 | J29: 0 | K29: 0-0-0 | L29: 0-0-0 | M29: 0-0-0 | N29: 0-0-0 | O29: 0 | P29: 0 | Q29: 0 | R29: 0-0 | S29: 0-0-0
A30: St. Louis Blues | B30: 0 | C30: 0 | D30: 0 | E30: 0 | F30: 0 | G30: 0 | H30: 0 | I30: 0 | J30: 0 | K30: 0-0-0 | L30: 0-0-0 | M30: 0-0-0 | N30: 0-0-0 | O30: 0 | P30: 0 | Q30: 0 | R30: 0-0 | S30: 0-0-0
A31: Utah Mammoth | B31: 0 | C31: 0 | D31: 0 | E31: 0 | F31: 0 | G31: 0 | H31: 0 | I31: 0 | J31: 0 | K31: 0-0-0 | L31: 0-0-0 | M31: 0-0-0 | N31: 0-0-0 | O31: 0 | P31: 0 | Q31: 0 | R31: 0-0 | S31: 0-0-0
A32: Winnipeg Jets | B32: 0 | C32: 0 | D32: 0 | E32: 0 | F32: 0 | G32: 0 | H32: 0 | I32: 0 | J32: 0 | K32: 0-0-0 | L32: 0-0-0 | M32: 0-0-0 | N32: 0-0-0 | O32: 0 | P32: 0 | Q32: 0 | R32: 0-0 | S32: 0-0-0
A33: Pacific
A34: Team | B34: GP | C34: W | D34: L | E34: OTL | F34: PTS | G34: RW | H34: ROW | I34: SOW | J34: SOL | K34: Home | L34: Away | M34: Division | N34: Conference | O34: GF | P34: GA | Q34: Diff | R34: Strk | S34: L10
A35: Anaheim Ducks | B35: 0 | C35: 0 | D35: 0 | E35: 0 | F35: 0 | G35: 0 | H35: 0 | I35: 0 | J35: 0 | K35: 0-0-0 | L35: 0-0-0 | M35: 0-0-0 | N35: 0-0-0 | O35: 0 | P35: 0 | Q35: 0 | R35: 0-0 | S35: 0-0-0
A36: Calgary Flames | B36: 0 | C36: 0 | D36: 0 | E36: 0 | F36: 0 | G36: 0 | H36: 0 | I36: 0 | J36: 0 | K36: 0-0-0 | L36: 0-0-0 | M36: 0-0-0 | N36: 0-0-0 | O36: 0 | P36: 0 | Q36: 0 | R36: 0-0 | S36: 0-0-0
A37: Edmonton Oilers | B37: 0 | C37: 0 | D37: 0 | E37: 0 | F37: 0 | G37: 0 | H37: 0 | I37: 0 | J37: 0 | K37: 0-0-0 | L37: 0-0-0 | M37: 0-0-0 | N37: 0-0-0 | O37: 0 | P37: 0 | Q37: 0 | R37: 0-0 | S37: 0-0-0
A38: Los Angeles Kings | B38: 1 | C38: 0 | D38: 1 | E38: 0 | F38: 0 | G38: 0 | H38: 0 | I38: 0 | J38: 0 | K38: 0-1-0 | L38: 0-0-0 | M38: 0-0-0 | N38: 0-1-0 | O38: 1 | P38: 4 | Q38: -3 | R38: L1 | S38: 0-1-0
A39: San Jose Sharks | B39: 0 | C39: 0 | D39: 0 | E39: 0 | F39: 0 | G39: 0 | H39: 0 | I39: 0 | J39: 0 | K39: 0-0-0 | L39: 0-0-0 | M39: 0-0-0 | N39: 0-0-0 | O39: 0 | P39: 0 | Q39: 0 | R39: 0-0 | S39: 0-0-0
A40: Seattle Kraken | B40: 0 | C40: 0 | D40: 0 | E40: 0 | F40: 0 | G40: 0 | H40: 0 | I40: 0 | J40: 0 | K40: 0-0-0 | L40: 0-0-0 | M40: 0-0-0 | N40: 0-0-0 | O40: 0 | P40: 0 | Q40: 0 | R40: 0-0 | S40: 0-0-0
...

Sheet Standings (10_8_25)
A1: Eastern Conference | T1: HOME
A2: Atlantic
A3: Team | B3: GP | C3: W | D3: L | E3: OTL | F3: PTS | G3: RW | H3: ROW | I3: SOW | J3: SOL | K3: Home | L3: Away | M3: Division | N3: Conference | O3: GF | P3: GA | Q3: Diff | R3: Strk | S3: L10
A4: Boston Bruins | B4: 1 | C4: 1 | D4: 0 | E4: 0 | F4: 2 | G4: 1 | H4: 1 | I4: 0 | J4: 0 | K4: 0-0-0 | L4: 1-0-0 | M4: 0-0-0 | N4: 1-0-0 | O4: 3 | P4: 1 | Q4: 2 | R4: W1 | S4: 1-0-0
A5: Florida Panthers | B5: 1 | C5: 1 | D5: 0 | E5: 0 | F5: 2 | G5: 1 | H5: 1 | I5: 0 | J5: 0 | K5: 1-0-0 | L5: 0-0-0 | M5: 0-0-0 | N5: 0-0-0 | O5: 3 | P5: 2 | Q5: 1 | R5: W1 | S5: 1-0-0
A6: Toronto Maple Leafs | B6: 1 | C6: 1 | D6: 0 | E6: 0 | F6: 2 | G6: 1 | H6: 1 | I6: 0 | J6: 0 | K6: 1-0-0 | L6: 0-0-0 | M6: 1-0-0 | N6: 1-0-0 | O6: 5 | P6: 2 | Q6: 3 | R6: W1 | S6: 1-0-0
A7: Buffalo Sabres | B7: 0 | C7: 0 | D7: 0 | E7: 0 | F7: 0 | G7: 0 | H7: 0 | I7: 0 | J7: 0 | K7: 0-0-0 | L7: 0-0-0 | M7: 0-0-0 | N7: 0-0-0 | O7: 0 | P7: 0 | Q7: 0 | R7: 0-0 | S7: 0-0-0
A8: Detroit Red Wings | B8: 0 | C8: 0 | D8: 0 | E8: 0 | F8: 0 | G8: 0 | H8: 0 | I8: 0 | J8: 0 | K8: 0-0-0 | L8: 0-0-0 | M8: 0-0-0 | N8: 0-0-0 | O8: 0 | P8: 0 | Q8: 0 | R8: 0-0 | S8: 0-0-0
A9: Montreal Canadiens | B9: 1 | C9: 0 | D9: 1 | E9: 0 | F9: 0 | G9: 0 | H9: 0 | I9: 0 | J9: 0 | K9: 0-0-0 | L9: 0-1-0 | M9: 0-1-0 | N9: 0-1-0 | O9: 2 | P9: 5 | Q9: -3 | R9: L1 | S9: 0-1-0
A10: Ottawa Senators | B10: 0 | C10: 0 | D10: 0 | E10: 0 | F10: 0 | G10: 0 | H10: 0 | I10: 0 | J10: 0 | K10: 0-0-0 | L10: 0-0-0 | M10: 0-0-0 | N10: 0-0-0 | O10: 0 | P10: 0 | Q10: 0 | R10: 0-0 | S10: 0-0-0
A11: Tampa Bay Lightning | B11: 0 | C11: 0 | D11: 0 | E11: 0 | F11: 0 | G11: 0 | H11: 0 | I11: 0 | J11: 0 | K11: 0-0-0 | L11: 0-0-0 | M11: 0-0-0 | N11: 0-0-0 | O11: 0 | P11: 0 | Q11: 0 | R11: 0-0 | S11: 0-0-0
A12: Metropolitan
A13: Team | B13: GP | C13: W | D13: L | E13: OTL | F13: PTS | G13: RW | H13: ROW | I13: SOW | J13: SOL | K13: Home | L13: Away | M13: Division | N13: Conference | O13: GF | P13: GA | Q13: Diff | R13: Strk | S13: L10
A14: Pittsburgh Penguins | B14: 1 | C14: 1 | D14: 0 | E14: 0 | F14: 2 | G14: 1 | H14: 1 | I14: 0 | J14: 0 | K14: 0-0-0 | L14: 1-0-0 | M14: 1-0-0 | N14: 1-0-0 | O14: 3 | P14: 0 | Q14: 3 | R14: W1 | S14: 1-0-0
A15: Carolina Hurricanes | B15: 0 | C15: 0 | D15: 0 | E15: 0 | F15: 0 | G15: 0 | H15: 0 | I15: 0 | J15: 0 | K15: 0-0-0 | L15: 0-0-0 | M15: 0-0-0 | N15: 0-0-0 | O15: 0 | P15: 0 | Q15: 0 | R15: 0-0 | S15: 0-0-0
A16: Columbus Blue Jackets | B16: 0 | C16: 0 | D16: 0 | E16: 0 | F16: 0 | G16: 0 | H16: 0 | I16: 0 | J16: 0 | K16: 0-0-0 | L16: 0-0-0 | M16: 0-0-0 | N16: 0-0-0 | O16: 0 | P16: 0 | Q16: 0 | R16: 0-0 | S16: 0-0-0
A17: New Jersey Devils | B17: 0 | C17: 0 | D17: 0 | E17: 0 | F17: 0 | G17: 0 | H17: 0 | I17: 0 | J17: 0 | K17: 0-0-0 | L17: 0-0-0 | M17: 0-0-0 | N17: 0-0-0 | O17: 0 | P17: 0 | Q17: 0 | R17: 0-0 | S17: 0-0-0
A18: New York Islanders | B18: 0 | C18: 0 | D18: 0 | E18: 0 | F18: 0 | G18: 0 | H18: 0 | I18: 0 | J18: 0 | K18: 0-0-0 | L18: 0-0-0 | M18: 0-0-0 | N18: 0-0-0 | O18: 0 | P18: 0 | Q18: 0 | R18: 0-0 | S18: 0-0-0
A19: New York Rangers | B19: 1 | C19: 0 | D19: 1 | E19: 0 | F19: 0 | G19: 0 | H19: 0 | I19: 0 | J19: 0 | K19: 0-1-0 | L19: 0-0-0 | M19: 0-1-0 | N19: 0-1-0 | O19: 0 | P19: 3 | Q19: -3 | R19: L1 | S19: 0-1-0
A20: Philadelphia Flyers | B20: 0 | C20: 0 | D20: 0 | E20: 0 | F20: 0 | G20: 0 | H20: 0 | I20: 0 | J20: 0 | K20: 0-0-0 | L20: 0-0-0 | M20: 0-0-0 | N20: 0-0-0 | O20: 0 | P20: 0 | Q20: 0 | R20: 0-0 | S20: 0-0-0
A21: Washington Capitals | B21: 1 | C21: 0 | D21: 1 | E21: 0 | F21: 0 | G21: 0 | H21: 0 | I21: 0 | J21: 0 | K21: 0-1-0 | L21: 0-0-0 | M21: 0-0-0 | N21: 0-1-0 | O21: 1 | P21: 3 | Q21: -2 | R21: L1 | S21: 0-1-0
A22: Western_Conference
A23: Central
A24: Team | B24: GP | C24: W | D24: L | E24: OTL | F24: PTS | G24: RW | H24: ROW | I24: SOW | J24: SOL | K24: Home | L24: Away | M24: Division | N24: Conference | O24: GF | P24: GA | Q24: Diff | R24: Strk | S24: L10
A25: Colorado Avalanche | B25: 1 | C25: 1 | D25: 0 | E25: 0 | F25: 2 | G25: 1 | H25: 1 | I25: 0 | J25: 0 | K25: 0-0-0 | L25: 1-0-0 | M25: 0-0-0 | N25: 1-0-0 | O25: 4 | P25: 1 | Q25: 3 | R25: W1 | S25: 1-0-0
A26: Chicago Blackhawks | B26: 1 | C26: 0 | D26: 1 | E26: 0 | F26: 0 | G26: 0 | H26: 0 | I26: 0 | J26: 0 | K26: 0-0-0 | L26: 0-1-0 | M26: 0-0-0 | N26: 0-0-0 | O26: 2 | P26: 3 | Q26: -1 | R26: L1 | S26: 0-1-0
A27: Dallas Stars | B27: 0 | C27: 0 | D27: 0 | E27: 0 | F27: 0 | G27: 0 | H27: 0 | I27: 0 | J27: 0 | K27: 0-0-0 | L27: 0-0-0 | M27: 0-0-0 | N27: 0-0-0 | O27: 0 | P27: 0 | Q27: 0 | R27: 0-0 | S27: 0-0-0
A28: Minnesota Wild | B28: 0 | C28: 0 | D28: 0 | E28: 0 | F28: 0 | G28: 0 | H28: 0 | I28: 0 | J28: 0 | K28: 0-0-0 | L28: 0-0-0 | M28: 0-0-0 | N28: 0-0-0 | O28: 0 | P28: 0 | Q28: 0 | R28: 0-0 | S28: 0-0-0
A29: Nashville Predators | B29: 0 | C29: 0 | D29: 0 | E29: 0 | F29: 0 | G29: 0 | H29: 0 | I29: 0 | J29: 0 | K29: 0-0-0 | L29: 0-0-0 | M29: 0-0-0 | N29: 0-0-0 | O29: 0 | P29: 0 | Q29: 0 | R29: 0-0 | S29: 0-0-0
A30: St. Louis Blues | B30: 0 | C30: 0 | D30: 0 | E30: 0 | F30: 0 | G30: 0 | H30: 0 | I30: 0 | J30: 0 | K30: 0-0-0 | L30: 0-0-0 | M30: 0-0-0 | N30: 0-0-0 | O30: 0 | P30: 0 | Q30: 0 | R30: 0-0 | S30: 0-0-0
A31: Utah Mammoth | B31: 0 | C31: 0 | D31: 0 | E31: 0 | F31: 0 | G31: 0 | H31: 0 | I31: 0 | J31: 0 | K31: 0-0-0 | L31: 0-0-0 | M31: 0-0-0 | N31: 0-0-0 | O31: 0 | P31: 0 | Q31: 0 | R31: 0-0 | S31: 0-0-0
A32: Winnipeg Jets | B32: 0 | C32: 0 | D32: 0 | E32: 0 | F32: 0 | G32: 0 | H32: 0 | I32: 0 | J32: 0 | K32: 0-0-0 | L32: 0-0-0 | M32: 0-0-0 | N32: 0-0-0 | O32: 0 | P32: 0 | Q32: 0 | R32: 0-0 | S32: 0-0-0
A33: Pacific
A34: Team | B34: GP | C34: W | D34: L | E34: OTL | F34: PTS | G34: RW | H34: ROW | I34: SOW | J34: SOL | K34: Home | L34: Away | M34: Division | N34: Conference | O34: GF | P34: GA | Q34: Diff | R34: Strk | S34: L10
A35: Calgary Flames | B35: 1 | C35: 1 | D35: 0 | E35: 0 | F35: 2 | G35: 0 | H35: 0 | I35: 1 | J35: 0 | K35: 0-0-0 | L35: 1-0-0 | M35: 1-0-0 | N35: 1-0-0 | O35: 4 | P35: 3 | Q35: 1 | R35: W1 | S35: 1-0-0
A36: Los Angeles Kings | B36: 2 | C36: 1 | D36: 1 | E36: 0 | F36: 2 | G36: 0 | H36: 0 | I36: 1 | J36: 0 | K36: 0-1-0 | L36: 1-0-0 | M36: 1-0-0 | N36: 1-1-0 | O36: 7 | P36: 9 | Q36: -2 | R36: W1 | S36: 1-1-0
A37: Edmonton Oilers | B37: 1 | C37: 0 | D37: 0 | E37: 1 | F37: 1 | G37: 0 | H37: 0 | I37: 0 | J37: 1 | K37: 0-0-1 | L37: 0-0-0 | M37: 0-0-1 | N37: 0-0-1 | O37: 3 | P37: 4 | Q37: -1 | R37: L1 | S37: 0-0-1
A38: Vegas Golden Knights | B38: 1 | C38: 0 | D38: 0 | E38: 1 | F38: 1 | G38: 0 | H38: 0 | I38: 0 | J38: 1 | K38: 0-0-1 | L38: 0-0-0 | M38: 0-0-1 | N38: 0-0-1 | O38: 5 | P38: 6 | Q38: -1 | R38: L1 | S38: 0-0-1
A39: Anaheim Ducks | B39: 0 | C39: 0 | D39: 0 | E39: 0 | F39: 0 | G39: 0 | H39: 0 | I39: 0 | J39: 0 | K39: 0-0-0 | L39: 0-0-0 | M39: 0-0-0 | N39: 0-0-0 | O39: 0 | P39: 0 | Q39: 0 | R39: 0-0 | S39: 0-0-0
A40: San Jose Sharks | B40: 0 | C40: 0 | D40: 0 | E40: 0 | F40: 0 | G40: 0 | H40: 0 | I40: 0 | J40: 0 | K40: 0-0-0 | L40: 0-0-0 | M40: 0-0-0 | N40: 0-0-0 | O40: 0 | P40: 0 | Q40: 0 | R40: 0-0 | S40: 0-0-0
...

Sheet Standings (10_9_25)
A1: Eastern Conference | T1: HOME
A2: Atlantic
A3: Team | B3: GP | C3: W | D3: L | E3: OTL | F3: PTS | G3: RW | H3: ROW | I3: SOW | J3: SOL | K3: Home | L3: Away | M3: Division | N3: Conference | O3: GF | P3: GA | Q3: Diff | R3: Strk | S3: L10
A4: Boston Bruins | B4: 2 | C4: 2 | D4: 0 | E4: 0 | F4: 4 | G4: 1 | H4: 2 | I4: 0 | J4: 0 | K4: 1-0-0 | L4: 1-0-0 | M4: 0-0-0 | N4: 1-0-0 | O4: 7 | P4: 4 | Q4: 3 | R4: W2 | S4: 2-0-0
A5: Florida Panthers | B5: 2 | C5: 2 | D5: 0 | E5: 0 | F5: 4 | G5: 2 | H5: 2 | I5: 0 | J5: 0 | K5: 2-0-0 | L5: 0-0-0 | M5: 0-0-0 | N5: 1-0-0 | O5: 5 | P5: 3 | Q5: 2 | R5: W2 | S5: 2-0-0
A6: Montreal Canadiens | B6: 2 | C6: 1 | D6: 1 | E6: 0 | F6: 2 | G6: 1 | H6: 1 | I6: 0 | J6: 0 | K6: 0-0-0 | L6: 1-1-0 | M6: 1-1-0 | N6: 1-1-0 | O6: 7 | P6: 6 | Q6: 1 | R6: W1 | S6: 1-1-0
A7: Ottawa Senators | B7: 1 | C7: 1 | D7: 0 | E7: 0 | F7: 2 | G7: 1 | H7: 1 | I7: 0 | J7: 0 | K7: 0-0-0 | L7: 1-0-0 | M7: 1-0-0 | N7: 1-0-0 | O7: 5 | P7: 4 | Q7: 1 | R7: W1 | S7: 1-0-0
A8: Toronto Maple Leafs | B8: 1 | C8: 1 | D8: 0 | E8: 0 | F8: 2 | G8: 1 | H8: 1 | I8: 0 | J8: 0 | K8: 1-0-0 | L8: 0-0-0 | M8: 1-0-0 | N8: 1-0-0 | O8: 5 | P8: 2 | Q8: 3 | R8: W1 | S8: 1-0-0
A9: Buffalo Sabres | B9: 1 | C9: 0 | D9: 1 | E9: 0 | F9: 0 | G9: 0 | H9: 0 | I9: 0 | J9: 0 | K9: 0-1-0 | L9: 0-0-0 | M9: 0-0-0 | N9: 0-1-0 | O9: 0 | P9: 4 | Q9: -4 | R9: L1 | S9: 0-1-0
A10: Detroit Red Wings | B10: 1 | C10: 0 | D10: 1 | E10: 0 | F10: 0 | G10: 0 | H10: 0 | I10: 0 | J10: 0 | K10: 0-1-0 | L10: 0-0-0 | M10: 0-1-0 | N10: 0-1-0 | O10: 1 | P10: 5 | Q10: -4 | R10: L1 | S10: 0-1-0
A11: Tampa Bay Lightning | B11: 1 | C11: 0 | D11: 1 | E11: 0 | F11: 0 | G11: 0 | H11: 0 | I11: 0 | J11: 0 | K11: 0-1-0 | L11: 0-0-0 | M11: 0-1-0 | N11: 0-1-0 | O11: 4 | P11: 5 | Q11: -1 | R11: L1 | S11: 0-1-0
A12: Metropolitan
A13: Team | B13: GP | C13: W | D13: L | E13: OTL | F13: PTS | G13: RW | H13: ROW | I13: SOW | J13: SOL | K13: Home | L13: Away | M13: Division | N13: Conference | O13: GF | P13: GA | Q13: Diff | R13: Strk | S13: L10
A14: Pittsburgh Penguins | B14: 2 | C14: 2 | D14: 0 | E14: 0 | F14: 4 | G14: 2 | H14: 2 | I14: 0 | J14: 0 | K14: 1-0-0 | L14: 1-0-0 | M14: 2-0-0 | N14: 2-0-0 | O14: 7 | P14: 3 | Q14: 4 | R14: W2 | S14: 2-0-0
A15: Carolina Hurricanes | B15: 1 | C15: 1 | D15: 0 | E15: 0 | F15: 2 | G15: 1 | H15: 1 | I15: 0 | J15: 0 | K15: 1-0-0 | L15: 0-0-0 | M15: 1-0-0 | N15: 1-0-0 | O15: 6 | P15: 3 | Q15: 3 | R15: W1 | S15: 1-0-0
A16: New York Rangers | B16: 2 | C16: 1 | D16: 1 | E16: 0 | F16: 2 | G16: 1 | H16: 1 | I16: 0 | J16: 0 | K16: 0-1-0 | L16: 1-0-0 | M16: 0-1-0 | N16: 1-1-0 | O16: 4 | P16: 3 | Q16: 1 | R16: W1 | S16: 1-1-0
A17: Columbus Blue Jackets | B17: 1 | C17: 0 | D17: 1 | E17: 0 | F17: 0 | G17: 0 | H17: 0 | I17: 0 | J17: 0 | K17: 0-0-0 | L17: 0-1-0 | M17: 0-0-0 | N17: 0-0-0 | O17: 1 | P17: 2 | Q17: -1 | R17: L1 | S17: 0-1-0
A18: New Jersey Devils | B18: 1 | C18: 0 | D18: 1 | E18: 0 | F18: 0 | G18: 0 | H18: 0 | I18: 0 | J18: 0 | K18: 0-0-0 | L18: 0-1-0 | M18: 0-1-0 | N18: 0-1-0 | O18: 3 | P18: 6 | Q18: -3 | R18: L1 | S18: 0-1-0
A19: New York Islanders | B19: 1 | C19: 0 | D19: 1 | E19: 0 | F19: 0 | G19: 0 | H19: 0 | I19: 0 | J19: 0 | K19: 0-0-0 | L19: 0-1-0 | M19: 0-1-0 | N19: 0-1-0 | O19: 3 | P19: 4 | Q19: -1 | R19: L1 | S19: 0-1-0
A20: Philadelphia Flyers | B20: 1 | C20: 0 | D20: 1 | E20: 0 | F20: 0 | G20: 0 | H20: 0 | I20: 0 | J20: 0 | K20: 0-0-0 | L20: 0-1-0 | M20: 0-0-0 | N20: 0-1-0 | O20: 1 | P20: 2 | Q20: -1 | R20: L1 | S20: 0-1-0
A21: Washington Capitals | B21: 1 | C21: 0 | D21: 1 | E21: 0 | F21: 0 | G21: 0 | H21: 0 | I21: 0 | J21: 0 | K21: 0-1-0 | L21: 0-0-0 | M21: 0-0-0 | N21: 0-1-0 | O21: 1 | P21: 3 | Q21: -2 | R21: L1 | S21: 0-1-0
A22: Western_Conference
A23: Central
A24: Team | B24: GP | C24: W | D24: L | E24: OTL | F24: PTS | G24: RW | H24: ROW | I24: SOW | J24: SOL | K24: Home | L24: Away | M24: Division | N24: Conference | O24: GF | P24: GA | Q24: Diff | R24: Strk | S24: L10
A25: Colorado Avalanche | B25: 2 | C25: 2 | D25: 0 | E25: 0 | F25: 4 | G25: 2 | H25: 2 | I25: 0 | J25: 0 | K25: 1-0-0 | L25: 1-0-0 | M25: 1-0-0 | N25: 2-0-0 | O25: 6 | P25: 2 | Q25: 4 | R25: W2 | S25: 2-0-0
A26: Dallas Stars | B26: 1 | C26: 1 | D26: 0 | E26: 0 | F26: 2 | G26: 1 | H26: 1 | I26: 0 | J26: 0 | K26: 0-0-0 | L26: 1-0-0 | M26: 1-0-0 | N26: 1-0-0 | O26: 5 | P26: 4 | Q26: 1 | R26: W1 | S26: 1-0-0
A27: Minnesota Wild | B27: 1 | C27: 1 | D27: 0 | E27: 0 | F27: 2 | G27: 1 | H27: 1 | I27: 0 | J27: 0 | K27: 0-0-0 | L27: 1-0-0 | M27: 1-0-0 | N27: 1-0-0 | O27: 5 | P27: 0 | Q27: 5 | R27: W1 | S27: 1-0-0
A28: Nashville Predators | B28: 1 | C28: 1 | D28: 0 | E28: 0 | F28: 2 | G28: 1 | H28: 1 | I28: 0 | J28: 0 | K28: 1-0-0 | L28: 0-0-0 | M28: 0-0-0 | N28: 0-0-0 | O28: 2 | P28: 1 | Q28: 1 | R28: W1 | S28: 1-0-0
A29: Chicago Blackhawks | B29: 2 | C29: 0 | D29: 1 | E29: 1 | F29: 1 | G29: 0 | H29: 0 | I29: 0 | J29: 0 | K29: 0-0-0 | L29: 0-1-1 | M29: 0-0-0 | N29: 0-0-0 | O29: 5 | P29: 7 | Q29: -2 | R29: L2 | S29: 0-1-1
A30: St. Louis Blues | B30: 1 | C30: 0 | D30: 1 | E30: 0 | F30: 0 | G30: 0 | H30: 0 | I30: 0 | J30: 0 | K30: 0-1-0 | L30: 0-0-0 | M30: 0-1-0 | N30: 0-1-0 | O30: 0 | P30: 5 | Q30: -5 | R30: L1 | S30: 0-1-0
A31: Utah Mammoth | B31: 1 | C31: 0 | D31: 1 | E31: 0 | F31: 0 | G31: 0 | H31: 0 | I31: 0 | J31: 0 | K31: 0-0-0 | L31: 0-1-0 | M31: 0-1-0 | N31: 0-1-0 | O31: 1 | P31: 2 | Q31: -1 | R31: L1 | S31: 0-1-0
A32: Winnipeg Jets | B32: 1 | C32: 0 | D32: 1 | E32: 0 | F32: 0 | G32: 0 | H32: 0 | I32: 0 | J32: 0 | K32: 0-1-0 | L32: 0-0-0 | M32: 0-1-0 | N32: 0-1-0 | O32: 4 | P32: 5 | Q32: -1 | R32: L1 | S32: 0-1-0
A33: Pacific
A34: Team | B34: GP | C34: W | D34: L | E34: OTL | F34: PTS | G34: RW | H34: ROW | I34: SOW | J34: SOL | K34: Home | L34: Away | M34: Division | N34: Conference | O34: GF | P34: GA | Q34: Diff | R34: Strk | S34: L10
A35: Vegas Golden Knights | B35: 2 | C35: 1 | D35: 0 | E35: 1 | F35: 3 | G35: 0 | H35: 1 | I35: 0 | J35: 1 | K35: 0-0-1 | L35: 1-0-0 | M35: 1-0-1 | N35: 1-0-1 | O35: 9 | P35: 9 | Q35: 0 | R35: W1 | S35: 1-0-1
A36: Calgary Flames | B36: 2 | C36: 1 | D36: 1 | E36: 0 | F36: 2 | G36: 0 | H36: 0 | I36: 1 | J36: 0 | K36: 0-0-0 | L36: 1-1-0 | M36: 1-1-0 | N36: 1-1-0 | O36: 5 | P36: 8 | Q36: -3 | R36: L1 | S36: 1-1-0
A37: Los Angeles Kings | B37: 2 | C37: 1 | D37: 1 | E37: 0 | F37: 2 | G37: 0 | H37: 0 | I37: 1 | J37: 0 | K37: 0-1-0 | L37: 1-0-0 | M37: 1-0-0 | N37: 1-1-0 | O37: 7 | P37: 9 | Q37: -2 | R37: W1 | S37: 1-1-0
A38: Seattle Kraken | B38: 1 | C38: 1 | D38: 0 | E38: 0 | F38: 2 | G38: 1 | H38: 1 | I38: 0 | J38: 0 | K38: 1-0-0 | L38: 0-0-0 | M38: 1-0-0 | N38: 1-0-0 | O38: 3 | P38: 1 | Q38: 2 | R38: W1 | S38: 1-0-0
A39: Vancouver Canucks | B39: 1 | C39: 1 | D39: 0 | E39: 0 | F39: 2 | G39: 1 | H39: 1 | I39: 0 | J39: 0 | K39: 1-0-0 | L39: 0-0-0 | M39: 1-0-0 | N39: 1-0-0 | O39: 5 | P39: 1 | Q39: 4 | R39: W1 | S39: 1-0-0
A40: Edmonton Oilers | B40: 1 | C40: 0 | D40: 0 | E40: 1 | F40: 1 | G40: 0 | H40: 0 | I40: 0 | J40: 1 | K40: 0-0-1 | L40: 0-0-0 | M40: 0-0-1 | N40: 0-0-1 | O40: 3 | P40: 4 | Q40: -1 | R40: L1 | S40: 0-0-1
...

Sheet Standings (10_11_25)
A1: Eastern Conference | T1: HOME
A2: Atlantic
A3: Team | B3: GP | C3: W | D3: L | E3: OTL | F3: PTS | G3: RW | H3: ROW | I3: SOW | J3: SOL | K3: Home | L3: Away | M3: Division | N3: Conference | O3: GF | P3: GA | Q3: Diff | R3: Strk | S3: L10
A4: Boston Bruins | B4: 3 | C4: 3 | D4: 0 | E4: 0 | F4: 6 | G4: 2 | H4: 3 | I4: 0 | J4: 0 | K4: 2-0-0 | L4: 1-0-0 | M4: 1-0-0 | N4: 2-0-0 | O4: 10 | P4: 5 | Q4: 5 | R4: W3 | S4: 3-0-0
A5: Florida Panthers | B5: 3 | C5: 3 | D5: 0 | E5: 0 | F5: 6 | G5: 3 | H5: 3 | I5: 0 | J5: 0 | K5: 3-0-0 | L5: 0-0-0 | M5: 1-0-0 | N5: 2-0-0 | O5: 11 | P5: 5 | Q5: 6 | R5: W3 | S5: 3-0-0
A6: Montreal Canadiens | B6: 3 | C6: 2 | D6: 1 | E6: 0 | F6: 4 | G6: 2 | H6: 2 | I6: 0 | J6: 0 | K6: 0-0-0 | L6: 2-1-0 | M6: 1-1-0 | N6: 1-1-0 | O6: 10 | P6: 8 | Q6: 2 | R6: W2 | S6: 2-1-0
A7: Detroit Red Wings | B7: 2 | C7: 1 | D7: 1 | E7: 0 | F7: 2 | G7: 1 | H7: 1 | I7: 0 | J7: 0 | K7: 1-1-0 | L7: 0-0-0 | M7: 1-1-0 | N7: 1-1-0 | O7: 7 | P7: 8 | Q7: -1 | R7: W1 | S7: 1-1-0
A8: Ottawa Senators | B8: 2 | C8: 1 | D8: 1 | E8: 0 | F8: 2 | G8: 1 | H8: 1 | I8: 0 | J8: 0 | K8: 0-0-0 | L8: 1-1-0 | M8: 1-1-0 | N8: 1-1-0 | O8: 7 | P8: 10 | Q8: -3 | R8: L1 | S8: 1-1-0
A9: Toronto Maple Leafs | B9: 2 | C9: 1 | D9: 1 | E9: 0 | F9: 2 | G9: 1 | H9: 1 | I9: 0 | J9: 0 | K9: 1-0-0 | L9: 0-1-0 | M9: 1-1-0 | N9: 1-1-0 | O9: 8 | P9: 8 | Q9: 0 | R9: L1 | S9: 1-1-0
A10: Buffalo Sabres | B10: 2 | C10: 0 | D10: 2 | E10: 0 | F10: 0 | G10: 0 | H10: 0 | I10: 0 | J10: 0 | K10: 0-1-0 | L10: 0-1-0 | M10: 0-1-0 | N10: 0-2-0 | O10: 1 | P10: 7 | Q10: -6 | R10: L2 | S10: 0-2-0
A11: Tampa Bay Lightning | B11: 2 | C11: 0 | D11: 2 | E11: 0 | F11: 0 | G11: 0 | H11: 0 | I11: 0 | J11: 0 | K11: 0-2-0 | L11: 0-0-0 | M11: 0-1-0 | N11: 0-2-0 | O11: 7 | P11: 10 | Q11: -3 | R11: L2 | S11: 0-2-0
A12: Metropolitan
A13: Team | B13: GP | C13: W | D13: L | E13: OTL | F13: PTS | G13: RW | H13: ROW | I13: SOW | J13: SOL | K13: Home | L13: Away | M13: Division | N13: Conference | O13: GF | P13: GA | Q13: Diff | R13: Strk | S13: L10
A14: Carolina Hurricanes | B14: 2 | C14: 2 | D14: 0 | E14: 0 | F14: 4 | G14: 1 | H14: 2 | I14: 0 | J14: 0 | K14: 2-0-0 | L14: 0-0-0 | M14: 2-0-0 | N14: 2-0-0 | O14: 10 | P14: 6 | Q14: 4 | R14: W2 | S14: 2-0-0
A15: New York Rangers | B15: 3 | C15: 2 | D15: 1 | E15: 0 | F15: 4 | G15: 2 | H15: 2 | I15: 0 | J15: 0 | K15: 0-1-0 | L15: 2-0-0 | M15: 1-1-0 | N15: 2-1-0 | O15: 10 | P15: 4 | Q15: 6 | R15: W2 | S15: 2-1-0
A16: Pittsburgh Penguins | B16: 3 | C16: 2 | D16: 1 | E16: 0 | F16: 4 | G16: 2 | H16: 2 | I16: 0 | J16: 0 | K16: 1-1-0 | L16: 1-0-0 | M16: 2-1-0 | N16: 2-1-0 | O16: 8 | P16: 9 | Q16: -1 | R16: L1 | S16: 2-1-0
A17: Columbus Blue Jackets | B17: 2 | C17: 1 | D17: 1 | E17: 0 | F17: 2 | G17: 1 | H17: 1 | I17: 0 | J17: 0 | K17: 0-0-0 | L17: 1-1-0 | M17: 0-0-0 | N17: 0-0-0 | O17: 8 | P17: 6 | Q17: 2 | R17: W1 | S17: 1-1-0
A18: New Jersey Devils | B18: 2 | C18: 1 | D18: 1 | E18: 0 | F18: 2 | G18: 1 | H18: 1 | I18: 0 | J18: 0 | K18: 0-0-0 | L18: 1-1-0 | M18: 0-1-0 | N18: 1-1-0 | O18: 8 | P18: 9 | Q18: -1 | R18: W1 | S18: 1-1-0
A19: Washington Capitals | B19: 2 | C19: 1 | D19: 1 | E19: 0 | F19: 2 | G19: 1 | H19: 1 | I19: 0 | J19: 0 | K19: 0-1-0 | L19: 1-0-0 | M19: 1-0-0 | N19: 1-1-0 | O19: 5 | P19: 5 | Q19: 0 | R19: W1 | S19: 1-1-0
A20: Philadelphia Flyers | B20: 2 | C20: 0 | D20: 1 | E20: 1 | F20: 1 | G20: 0 | H20: 0 | I20: 0 | J20: 0 | K20: 0-0-0 | L20: 0-1-1 | M20: 0-0-1 | N20: 0-1-1 | O20: 4 | P20: 6 | Q20: -2 | R20: L2 | S20: 0-1-1
A21: New York Islanders | B21: 2 | C21: 0 | D21: 2 | E21: 0 | F21: 0 | G21: 0 | H21: 0 | I21: 0 | J21: 0 | K21: 0-1-0 | L21: 0-1-0 | M21: 0-2-0 | N21: 0-2-0 | O21: 5 | P21: 8 | Q21: -3 | R21: L2 | S21: 0-2-0
A22: Western_Conference
A23: Central
A24: Team | B24: GP | C24: W | D24: L | E24: OTL | F24: PTS | G24: RW | H24: ROW | I24: SOW | J24: SOL | K24: Home | L24: Away | M24: Division | N24: Conference | O24: GF | P24: GA | Q24: Diff | R24: Strk | S24: L10
A25: Colorado Avalanche | B25: 3 | C25: 2 | D25: 0 | E25: 1 | F25: 5 | G25: 2 | H25: 2 | I25: 0 | J25: 1 | K25: 1-0-1 | L25: 1-0-0 | M25: 1-0-1 | N25: 2-0-1 | O25: 10 | P25: 7 | Q25: 3 | R25: L1 | S25: 2-0-1
A26: Dallas Stars | B26: 2 | C26: 2 | D26: 0 | E26: 0 | F26: 4 | G26: 0 | H26: 1 | I26: 1 | J26: 0 | K26: 0-0-0 | L26: 2-0-0 | M26: 2-0-0 | N26: 2-0-0 | O26: 10 | P26: 8 | Q26: 2 | R26: W2 | S26: 2-0-0
A27: Nashville Predators | B27: 2 | C27: 1 | D27: 0 | E27: 1 | F27: 3 | G27: 1 | H27: 1 | I27: 0 | J27: 0 | K27: 1-0-1 | L27: 0-0-0 | M27: 0-0-1 | N27: 0-0-1 | O27: 4 | P27: 4 | Q27: 0 | R27: L1 | S27: 1-0-1
A28: Minnesota Wild | B28: 2 | C28: 1 | D28: 1 | E28: 0 | F28: 2 | G28: 1 | H28: 1 | I28: 0 | J28: 0 | K28: 0-1-0 | L28: 1-0-0 | M28: 1-0-0 | N28: 1-0-0 | O28: 9 | P28: 7 | Q28: 2 | R28: L1 | S28: 1-1-0
A29: St. Louis Blues | B29: 2 | C29: 1 | D29: 1 | E29: 0 | F29: 2 | G29: 1 | H29: 1 | I29: 0 | J29: 0 | K29: 0-1-0 | L29: 1-0-0 | M29: 0-1-0 | N29: 1-1-0 | O29: 4 | P29: 7 | Q29: -3 | R29: W1 | S29: 1-1-0
A30: Utah Mammoth | B30: 2 | C30: 1 | D30: 1 | E30: 0 | F30: 2 | G30: 0 | H30: 1 | I30: 0 | J30: 0 | K30: 0-0-0 | L30: 1-1-0 | M30: 1-1-0 | N30: 1-1-0 | O30: 4 | P30: 4 | Q30: 0 | R30: W1 | S30: 1-1-0
A31: Winnipeg Jets | B31: 2 | C31: 1 | D31: 1 | E31: 0 | F31: 2 | G31: 1 | H31: 1 | I31: 0 | J31: 0 | K31: 1-1-0 | L31: 0-0-0 | M31: 0-1-0 | N31: 1-1-0 | O31: 7 | P31: 7 | Q31: 0 | R31: W1 | S31: 1-1-0
A32: Chicago Blackhawks | B32: 3 | C32: 0 | D32: 2 | E32: 1 | F32: 1 | G32: 0 | H32: 0 | I32: 0 | J32: 0 | K32: 0-1-0 | L32: 0-1-1 | M32: 0-0-0 | N32: 0-0-0 | O32: 7 | P32: 10 | Q32: -3 | R32: L3 | S32: 0-2-1
A33: Pacific
A34: Team | B34: GP | C34: W | D34: L | E34: OTL | F34: PTS | G34: RW | H34: ROW | I34: SOW | J34: SOL | K34: Home | L34: Away | M34: Division | N34: Conference | O34: GF | P34: GA | Q34: Diff | R34: Strk | S34: L10
A35: Seattle Kraken | B35: 2 | C35: 2 | D35: 0 | E35: 0 | F35: 4 | G35: 1 | H35: 2 | I35: 0 | J35: 0 | K35: 2-0-0 | L35: 0-0-0 | M35: 2-0-0 | N35: 2-0-0 | O35: 5 | P35: 2 | Q35: 3 | R35: W2 | S35: 2-0-0
A36: Vegas Golden Knights | B36: 3 | C36: 1 | D36: 0 | E36: 2 | F36: 4 | G36: 0 | H36: 1 | I36: 0 | J36: 1 | K36: 0-0-1 | L36: 1-0-1 | M36: 1-0-2 | N36: 1-0-2 | O36: 10 | P36: 11 | Q36: -1 | R36: L1 | S36: 1-0-2
A37: Edmonton Oilers | B37: 2 | C37: 1 | D37: 0 | E37: 1 | F37: 3 | G37: 1 | H37: 1 | I37: 0 | J37: 1 | K37: 1-0-1 | L37: 0-0-0 | M37: 1-0-1 | N37: 1-0-1 | O37: 6 | P37: 5 | Q37: 1 | R37: W1 | S37: 1-0-1
A38: Anaheim Ducks | B38: 2 | C38: 1 | D38: 1 | E38: 0 | F38: 2 | G38: 0 | H38: 1 | I38: 0 | J38: 0 | K38: 0-0-0 | L38: 1-1-0 | M38: 1-1-0 | N38: 1-1-0 | O38: 8 | P38: 9 | Q38: -1 | R38: W1 | S38: 1-1-0
A39: Calgary Flames | B39: 3 | C39: 1 | D39: 2 | E39: 0 | F39: 2 | G39: 0 | H39: 0 | I39: 1 | J39: 0 | K39: 0-1-0 | L39: 1-1-0 | M39: 1-1-0 | N39: 1-2-0 | O39: 7 | P39: 12 | Q39: -5 | R39: L2 | S39: 1-2-0
A40: Los Angeles Kings | B40: 3 | C40: 1 | D40: 2 | E40: 0 | F40: 2 | G40: 0 | H40: 0 | I40: 1 | J40: 0 | K40: 0-1-0 | L40: 1-1-0 | M40: 1-0-0 | N40: 1-2-0 | O40: 9 | P40: 12 | Q40: -3 | R40: L1 | S40: 1-2-0
...

Sheet Standings (10_12_25)
A1: Eastern Conference | T1: HOME
A2: Atlantic
A3: Team | B3: GP | C3: W | D3: L | E3: OTL | F3: PTS | G3: RW | H3: ROW | I3: SOW | J3: SOL | K3: Home | L3: Away | M3: Division | N3: Conference | O3: GF | P3: GA | Q3: Diff | R3: Strk | S3: L10
A4: Boston Bruins | B4: 3 | C4: 3 | D4: 0 | E4: 0 | F4: 6 | G4: 2 | H4: 3 | I4: 0 | J4: 0 | K4: 2-0-0 | L4: 1-0-0 | M4: 1-0-0 | N4: 2-0-0 | O4: 10 | P4: 5 | Q4: 5 | R4: W3 | S4: 3-0-0
A5: Florida Panthers | B5: 3 | C5: 3 | D5: 0 | E5: 0 | F5: 6 | G5: 3 | H5: 3 | I5: 0 | J5: 0 | K5: 3-0-0 | L5: 0-0-0 | M5: 1-0-0 | N5: 2-0-0 | O5: 11 | P5: 5 | Q5: 6 | R5: W3 | S5: 3-0-0
A6: Montreal Canadiens | B6: 3 | C6: 2 | D6: 1 | E6: 0 | F6: 4 | G6: 2 | H6: 2 | I6: 0 | J6: 0 | K6: 0-0-0 | L6: 2-1-0 | M6: 1-1-0 | N6: 1-1-0 | O6: 10 | P6: 8 | Q6: 2 | R6: W2 | S6: 2-1-0
A7: Detroit Red Wings | B7: 2 | C7: 1 | D7: 1 | E7: 0 | F7: 2 | G7: 1 | H7: 1 | I7: 0 | J7: 0 | K7: 1-1-0 | L7: 0-0-0 | M7: 1-1-0 | N7: 1-1-0 | O7: 7 | P7: 8 | Q7: -1 | R7: W1 | S7: 1-1-0
A8: Ottawa Senators | B8: 2 | C8: 1 | D8: 1 | E8: 0 | F8: 2 | G8: 1 | H8: 1 | I8: 0 | J8: 0 | K8: 0-0-0 | L8: 1-1-0 | M8: 1-1-0 | N8: 1-1-0 | O8: 7 | P8: 10 | Q8: -3 | R8: L1 | S8: 1-1-0
A9: Toronto Maple Leafs | B9: 2 | C9: 1 | D9: 1 | E9: 0 | F9: 2 | G9: 1 | H9: 1 | I9: 0 | J9: 0 | K9: 1-0-0 | L9: 0-1-0 | M9: 1-1-0 | N9: 1-1-0 | O9: 8 | P9: 8 | Q9: 0 | R9: L1 | S9: 1-1-0
A10: Buffalo Sabres | B10: 2 | C10: 0 | D10: 2 | E10: 0 | F10: 0 | G10: 0 | H10: 0 | I10: 0 | J10: 0 | K10: 0-1-0 | L10: 0-1-0 | M10: 0-1-0 | N10: 0-2-0 | O10: 1 | P10: 7 | Q10: -6 | R10: L2 | S10: 0-2-0
A11: Tampa Bay Lightning | B11: 2 | C11: 0 | D11: 2 | E11: 0 | F11: 0 | G11: 0 | H11: 0 | I11: 0 | J11: 0 | K11: 0-2-0 | L11: 0-0-0 | M11: 0-1-0 | N11: 0-2-0 | O11: 7 | P11: 10 | Q11: -3 | R11: L2 | S11: 0-2-0
A12: Metropolitan
A13: Team | B13: GP | C13: W | D13: L | E13: OTL | F13: PTS | G13: RW | H13: ROW | I13: SOW | J13: SOL | K13: Home | L13: Away | M13: Division | N13: Conference | O13: GF | P13: GA | Q13: Diff | R13: Strk | S13: L10
A14: Carolina Hurricanes | B14: 2 | C14: 2 | D14: 0 | E14: 0 | F14: 4 | G14: 1 | H14: 2 | I14: 0 | J14: 0 | K14: 2-0-0 | L14: 0-0-0 | M14: 2-0-0 | N14: 2-0-0 | O14: 10 | P14: 6 | Q14: 4 | R14: W2 | S14: 2-0-0
A15: New York Rangers | B15: 4 | C15: 2 | D15: 2 | E15: 0 | F15: 4 | G15: 2 | H15: 2 | I15: 0 | J15: 0 | K15: 0-2-0 | L15: 2-0-0 | M15: 1-2-0 | N15: 2-2-0 | O15: 10 | P15: 5 | Q15: 5 | R15: L1 | S15: 2-2-0
A16: Pittsburgh Penguins | B16: 3 | C16: 2 | D16: 1 | E16: 0 | F16: 4 | G16: 2 | H16: 2 | I16: 0 | J16: 0 | K16: 1-1-0 | L16: 1-0-0 | M16: 2-1-0 | N16: 2-1-0 | O16: 8 | P16: 9 | Q16: -1 | R16: L1 | S16: 2-1-0
A17: Washington Capitals | B17: 3 | C17: 2 | D17: 1 | E17: 0 | F17: 4 | G17: 2 | H17: 2 | I17: 0 | J17: 0 | K17: 0-1-0 | L17: 2-0-0 | M17: 2-0-0 | N17: 2-1-0 | O17: 6 | P17: 5 | Q17: 1 | R17: W2 | S17: 2-1-0
A18: Columbus Blue Jackets | B18: 2 | C18: 1 | D18: 1 | E18: 0 | F18: 2 | G18: 1 | H18: 1 | I18: 0 | J18: 0 | K18: 0-0-0 | L18: 1-1-0 | M18: 0-0-0 | N18: 0-0-0 | O18: 8 | P18: 6 | Q18: 2 | R18: W1 | S18: 1-1-0
A19: New Jersey Devils | B19: 2 | C19: 1 | D19: 1 | E19: 0 | F19: 2 | G19: 1 | H19: 1 | I19: 0 | J19: 0 | K19: 0-0-0 | L19: 1-1-0 | M19: 0-1-0 | N19: 1-1-0 | O19: 8 | P19: 9 | Q19: -1 | R19: W1 | S19: 1-1-0
A20: Philadelphia Flyers | B20: 2 | C20: 0 | D20: 1 | E20: 1 | F20: 1 | G20: 0 | H20: 0 | I20: 0 | J20: 0 | K20: 0-0-0 | L20: 0-1-1 | M20: 0-0-1 | N20: 0-1-1 | O20: 4 | P20: 6 | Q20: -2 | R20: L2 | S20: 0-1-1
A21: New York Islanders | B21: 2 | C21: 0 | D21: 2 | E21: 0 | F21: 0 | G21: 0 | H21: 0 | I21: 0 | J21: 0 | K21: 0-1-0 | L21: 0-1-0 | M21: 0-2-0 | N21: 0-2-0 | O21: 5 | P21: 8 | Q21: -3 | R21: L2 | S21: 0-2-0
A22: Western_Conference
A23: Central
A24: Team | B24: GP | C24: W | D24: L | E24: OTL | F24: PTS | G24: RW | H24: ROW | I24: SOW | J24: SOL | K24: Home | L24: Away | M24: Division | N24: Conference | O24: GF | P24: GA | Q24: Diff | R24: Strk | S24: L10
A25: Colorado Avalanche | B25: 3 | C25: 2 | D25: 0 | E25: 1 | F25: 5 | G25: 2 | H25: 2 | I25: 0 | J25: 1 | K25: 1-0-1 | L25: 1-0-0 | M25: 1-0-1 | N25: 2-0-1 | O25: 10 | P25: 7 | Q25: 3 | R25: L1 | S25: 2-0-1
A26: Dallas Stars | B26: 2 | C26: 2 | D26: 0 | E26: 0 | F26: 4 | G26: 0 | H26: 1 | I26: 1 | J26: 0 | K26: 0-0-0 | L26: 2-0-0 | M26: 2-0-0 | N26: 2-0-0 | O26: 10 | P26: 8 | Q26: 2 | R26: W2 | S26: 2-0-0
A27: Nashville Predators | B27: 2 | C27: 1 | D27: 0 | E27: 1 | F27: 3 | G27: 1 | H27: 1 | I27: 0 | J27: 0 | K27: 1-0-1 | L27: 0-0-0 | M27: 0-0-1 | N27: 0-0-1 | O27: 4 | P27: 4 | Q27: 0 | R27: L1 | S27: 1-0-1
A28: Minnesota Wild | B28: 2 | C28: 1 | D28: 1 | E28: 0 | F28: 2 | G28: 1 | H28: 1 | I28: 0 | J28: 0 | K28: 0-1-0 | L28: 1-0-0 | M28: 1-0-0 | N28: 1-0-0 | O28: 9 | P28: 7 | Q28: 2 | R28: L1 | S28: 1-1-0
A29: St. Louis Blues | B29: 2 | C29: 1 | D29: 1 | E29: 0 | F29: 2 | G29: 1 | H29: 1 | I29: 0 | J29: 0 | K29: 0-1-0 | L29: 1-0-0 | M29: 0-1-0 | N29: 1-1-0 | O29: 4 | P29: 7 | Q29: -3 | R29: W1 | S29: 1-1-0
A30: Utah Mammoth | B30: 2 | C30: 1 | D30: 1 | E30: 0 | F30: 2 | G30: 0 | H30: 1 | I30: 0 | J30: 0 | K30: 0-0-0 | L30: 1-1-0 | M30: 1-1-0 | N30: 1-1-0 | O30: 4 | P30: 4 | Q30: 0 | R30: W1 | S30: 1-1-0
A31: Winnipeg Jets | B31: 2 | C31: 1 | D31: 1 | E31: 0 | F31: 2 | G31: 1 | H31: 1 | I31: 0 | J31: 0 | K31: 1-1-0 | L31: 0-0-0 | M31: 0-1-0 | N31: 1-1-0 | O31: 7 | P31: 7 | Q31: 0 | R31: W1 | S31: 1-1-0
A32: Chicago Blackhawks | B32: 3 | C32: 0 | D32: 2 | E32: 1 | F32: 1 | G32: 0 | H32: 0 | I32: 0 | J32: 0 | K32: 0-1-0 | L32: 0-1-1 | M32: 0-0-0 | N32: 0-0-0 | O32: 7 | P32: 10 | Q32: -3 | R32: L3 | S32: 0-2-1
A33: Pacific
A34: Team | B34: GP | C34: W | D34: L | E34: OTL | F34: PTS | G34: RW | H34: ROW | I34: SOW | J34: SOL | K34: Home | L34: Away | M34: Division | N34: Conference | O34: GF | P34: GA | Q34: Diff | R34: Strk | S34: L10
A35: Seattle Kraken | B35: 2 | C35: 2 | D35: 0 | E35: 0 | F35: 4 | G35: 1 | H35: 2 | I35: 0 | J35: 0 | K35: 2-0-0 | L35: 0-0-0 | M35: 2-0-0 | N35: 2-0-0 | O35: 5 | P35: 2 | Q35: 3 | R35: W2 | S35: 2-0-0
A36: Vegas Golden Knights | B36: 3 | C36: 1 | D36: 0 | E36: 2 | F36: 4 | G36: 0 | H36: 1 | I36: 0 | J36: 1 | K36: 0-0-1 | L36: 1-0-1 | M36: 1-0-2 | N36: 1-0-2 | O36: 10 | P36: 11 | Q36: -1 | R36: L1 | S36: 1-0-2
A37: Edmonton Oilers | B37: 2 | C37: 1 | D37: 0 | E37: 1 | F37: 3 | G37: 1 | H37: 1 | I37: 0 | J37: 1 | K37: 1-0-1 | L37: 0-0-0 | M37: 1-0-1 | N37: 1-0-1 | O37: 6 | P37: 5 | Q37: 1 | R37: W1 | S37: 1-0-1
A38: Anaheim Ducks | B38: 2 | C38: 1 | D38: 1 | E38: 0 | F38: 2 | G38: 0 | H38: 1 | I38: 0 | J38: 0 | K38: 0-0-0 | L38: 1-1-0 | M38: 1-1-0 | N38: 1-1-0 | O38: 8 | P38: 9 | Q38: -1 | R38: W1 | S38: 1-1-0
A39: Calgary Flames | B39: 3 | C39: 1 | D39: 2 | E39: 0 | F39: 2 | G39: 0 | H39: 0 | I39: 1 | J39: 0 | K39: 0-1-0 | L39: 1-1-0 | M39: 1-1-0 | N39: 1-2-0 | O39: 7 | P39: 12 | Q39: -5 | R39: L2 | S39: 1-2-0
A40: Los Angeles Kings | B40: 3 | C40: 1 | D40: 2 | E40: 0 | F40: 2 | G40: 0 | H40: 0 | I40: 1 | J40: 0 | K40: 0-1-0 | L40: 1-1-0 | M40: 1-0-0 | N40: 1-2-0 | O40: 9 | P40: 12 | Q40: -3 | R40: L1 | S40: 1-2-0
...

Sheet Standings (10_13_25)
A1: Eastern Conference | T1: HOME
A2: Atlantic
A3: Team | B3: GP | C3: W | D3: L | E3: OTL | F3: PTS | G3: RW | H3: ROW | I3: SOW | J3: SOL | K3: Home | L3: Away | M3: Division | N3: Conference | O3: GF | P3: GA | Q3: Diff | R3: Strk | S3: L10
A4: Boston Bruins | B4: 4 | C4: 3 | D4: 1 | E4: 0 | F4: 6 | G4: 2 | H4: 3 | I4: 0 | J4: 0 | K4: 2-1-0 | L4: 1-0-0 | M4: 1-1-0 | N4: 2-1-0 | O4: 13 | P4: 9 | Q4: 4 | R4: L1 | S4: 3-1-0
A5: Florida Panthers | B5: 4 | C5: 3 | D5: 1 | E5: 0 | F5: 6 | G5: 3 | H5: 3 | I5: 0 | J5: 0 | K5: 3-0-0 | L5: 0-1-0 | M5: 1-0-0 | N5: 2-1-0 | O5: 13 | P5: 10 | Q5: 3 | R5: L1 | S5: 3-1-0
A6: Detroit Red Wings | B6: 3 | C6: 2 | D6: 1 | E6: 0 | F6: 4 | G6: 2 | H6: 2 | I6: 0 | J6: 0 | K6: 1-1-0 | L6: 1-0-0 | M6: 2-1-0 | N6: 2-1-0 | O6: 10 | P6: 10 | Q6: 0 | R6: W2 | S6: 2-1-0
A7: Montreal Canadiens | B7: 3 | C7: 2 | D7: 1 | E7: 0 | F7: 4 | G7: 2 | H7: 2 | I7: 0 | J7: 0 | K7: 0-0-0 | L7: 2-1-0 | M7: 1-1-0 | N7: 1-1-0 | O7: 10 | P7: 8 | Q7: 2 | R7: W2 | S7: 2-1-0
A8: Ottawa Senators | B8: 3 | C8: 1 | D8: 2 | E8: 0 | F8: 2 | G8: 1 | H8: 1 | I8: 0 | J8: 0 | K8: 0-1-0 | L8: 1-1-0 | M8: 1-1-0 | N8: 1-1-0 | O8: 8 | P8: 14 | Q8: -6 | R8: L2 | S8: 1-2-0
A9: Tampa Bay Lightning | B9: 3 | C9: 1 | D9: 2 | E9: 0 | F9: 2 | G9: 1 | H9: 1 | I9: 0 | J9: 0 | K9: 0-2-0 | L9: 1-0-0 | M9: 1-1-0 | N9: 1-2-0 | O9: 11 | P9: 13 | Q9: -2 | R9: W1 | S9: 1-2-0
A10: Toronto Maple Leafs | B10: 3 | C10: 1 | D10: 2 | E10: 0 | F10: 2 | G10: 1 | H10: 1 | I10: 0 | J10: 0 | K10: 1-1-0 | L10: 0-1-0 | M10: 1-2-0 | N10: 1-2-0 | O10: 10 | P10: 11 | Q10: -1 | R10: L2 | S10: 1-2-0
A11: Buffalo Sabres | B11: 3 | C11: 0 | D11: 3 | E11: 0 | F11: 0 | G11: 0 | H11: 0 | I11: 0 | J11: 0 | K11: 0-2-0 | L11: 0-1-0 | M11: 0-1-0 | N11: 0-2-0 | O11: 2 | P11: 10 | Q11: -8 | R11: L3 | S11: 0-3-0
A12: Metropolitan
A13: Team | B13: GP | C13: W | D13: L | E13: OTL | F13: PTS | G13: RW | H13: ROW | I13: SOW | J13: SOL | K13: Home | L13: Away | M13: Division | N13: Conference | O13: GF | P13: GA | Q13: Diff | R13: Strk | S13: L10
A14: Carolina Hurricanes | B14: 2 | C14: 2 | D14: 0 | E14: 0 | F14: 4 | G14: 1 | H14: 2 | I14: 0 | J14: 0 | K14: 2-0-0 | L14: 0-0-0 | M14: 2-0-0 | N14: 2-0-0 | O14: 10 | P14: 6 | Q14: 4 | R14: W2 | S14: 2-0-0
A15: New Jersey Devils | B15: 3 | C15: 2 | D15: 1 | E15: 0 | F15: 4 | G15: 2 | H15: 2 | I15: 0 | J15: 0 | K15: 0-0-0 | L15: 2-1-0 | M15: 1-1-0 | N15: 2-1-0 | O15: 11 | P15: 11 | Q15: 0 | R15: W2 | S15: 2-1-0
A16: New York Rangers | B16: 4 | C16: 2 | D16: 2 | E16: 0 | F16: 4 | G16: 2 | H16: 2 | I16: 0 | J16: 0 | K16: 0-2-0 | L16: 2-0-0 | M16: 1-2-0 | N16: 2-2-0 | O16: 10 | P16: 5 | Q16: 5 | R16: L1 | S16: 2-2-0
A17: Pittsburgh Penguins | B17: 3 | C17: 2 | D17: 1 | E17: 0 | F17: 4 | G17: 2 | H17: 2 | I17: 0 | J17: 0 | K17: 1-1-0 | L17: 1-0-0 | M17: 2-1-0 | N17: 2-1-0 | O17: 8 | P17: 9 | Q17: -1 | R17: L1 | S17: 2-1-0
A18: Washington Capitals | B18: 3 | C18: 2 | D18: 1 | E18: 0 | F18: 4 | G18: 2 | H18: 2 | I18: 0 | J18: 0 | K18: 0-1-0 | L18: 2-0-0 | M18: 2-0-0 | N18: 2-1-0 | O18: 6 | P18: 5 | Q18: 1 | R18: W2 | S18: 2-1-0
A19: Philadelphia Flyers | B19: 3 | C19: 1 | D19: 1 | E19: 1 | F19: 3 | G19: 1 | H19: 1 | I19: 0 | J19: 0 | K19: 1-0-0 | L19: 0-1-1 | M19: 0-0-1 | N19: 1-1-1 | O19: 9 | P19: 8 | Q19: 1 | R19: W1 | S19: 1-1-1
A20: Columbus Blue Jackets | B20: 3 | C20: 1 | D20: 2 | E20: 0 | F20: 2 | G20: 1 | H20: 1 | I20: 0 | J20: 0 | K20: 0-1-0 | L20: 1-1-0 | M20: 0-1-0 | N20: 0-1-0 | O20: 10 | P20: 9 | Q20: 1 | R20: L1 | S20: 1-2-0
A21: New York Islanders | B21: 3 | C21: 0 | D21: 3 | E21: 0 | F21: 0 | G21: 0 | H21: 0 | I21: 0 | J21: 0 | K21: 0-2-0 | L21: 0-1-0 | M21: 0-2-0 | N21: 0-2-0 | O21: 7 | P21: 13 | Q21: -6 | R21: L3 | S21: 0-3-0
A22: Western_Conference
A23: Central
A24: Team | B24: GP | C24: W | D24: L | E24: OTL | F24: PTS | G24: RW | H24: ROW | I24: SOW | J24: SOL | K24: Home | L24: Away | M24: Division | N24: Conference | O24: GF | P24: GA | Q24: Diff | R24: Strk | S24: L10
A25: Colorado Avalanche | B25: 4 | C25: 3 | D25: 0 | E25: 1 | F25: 7 | G25: 3 | H25: 3 | I25: 0 | J25: 1 | K25: 1-0-1 | L25: 2-0-0 | M25: 1-0-1 | N25: 2-0-1 | O25: 13 | P25: 8 | Q25: 5 | R25: W1 | S25: 3-0-1
A26: Nashville Predators | B26: 3 | C26: 2 | D26: 0 | E26: 1 | F26: 5 | G26: 2 | H26: 2 | I26: 0 | J26: 0 | K26: 1-0-1 | L26: 1-0-0 | M26: 0-0-1 | N26: 0-0-1 | O26: 8 | P26: 5 | Q26: 3 | R26: W1 | S26: 2-0-1
A27: Dallas Stars | B27: 2 | C27: 2 | D27: 0 | E27: 0 | F27: 4 | G27: 0 | H27: 1 | I27: 1 | J27: 0 | K27: 0-0-0 | L27: 2-0-0 | M27: 2-0-0 | N27: 2-0-0 | O27: 10 | P27: 8 | Q27: 2 | R27: W2 | S27: 2-0-0
A28: Minnesota Wild | B28: 3 | C28: 2 | D28: 1 | E28: 0 | F28: 4 | G28: 1 | H28: 1 | I28: 1 | J28: 0 | K28: 1-1-0 | L28: 1-0-0 | M28: 1-0-0 | N28: 2-0-0 | O28: 13 | P28: 10 | Q28: 3 | R28: W1 | S28: 2-1-0
A29: St. Louis Blues | B29: 3 | C29: 2 | D29: 1 | E29: 0 | F29: 4 | G29: 2 | H29: 2 | I29: 0 | J29: 0 | K29: 0-1-0 | L29: 2-0-0 | M29: 0-1-0 | N29: 2-1-0 | O29: 9 | P29: 9 | Q29: 0 | R29: W2 | S29: 2-1-0
A30: Winnipeg Jets | B30: 3 | C30: 2 | D30: 1 | E30: 0 | F30: 4 | G30: 2 | H30: 2 | I30: 0 | J30: 0 | K30: 1-1-0 | L30: 1-0-0 | M30: 0-1-0 | N30: 1-1-0 | O30: 12 | P30: 9 | Q30: 3 | R30: W2 | S30: 2-1-0
A31: Chicago Blackhawks | B31: 4 | C31: 1 | D31: 2 | E31: 1 | F31: 3 | G31: 1 | H31: 1 | I31: 0 | J31: 0 | K31: 1-1-0 | L31: 0-1-1 | M31: 1-0-0 | N31: 1-0-0 | O31: 10 | P31: 11 | Q31: -1 | R31: W1 | S31: 1-2-1
A32: Utah Mammoth | B32: 3 | C32: 1 | D32: 2 | E32: 0 | F32: 2 | G32: 0 | H32: 1 | I32: 0 | J32: 0 | K32: 0-0-0 | L32: 1-2-0 | M32: 1-2-0 | N32: 1-2-0 | O32: 5 | P32: 7 | Q32: -2 | R32: L1 | S32: 1-2-0
A33: Pacific
A34: Team | B34: GP | C34: W | D34: L | E34: OTL | F34: PTS | G34: RW | H34: ROW | I34: SOW | J34: SOL | K34: Home | L34: Away | M34: Division | N34: Conference | O34: GF | P34: GA | Q34: Diff | R34: Strk | S34: L10
A35: Seattle Kraken | B35: 2 | C35: 2 | D35: 0 | E35: 0 | F35: 4 | G35: 1 | H35: 2 | I35: 0 | J35: 0 | K35: 2-0-0 | L35: 0-0-0 | M35: 2-0-0 | N35: 2-0-0 | O35: 5 | P35: 2 | Q35: 3 | R35: W2 | S35: 2-0-0
A36: Vegas Golden Knights | B36: 3 | C36: 1 | D36: 0 | E36: 2 | F36: 4 | G36: 0 | H36: 1 | I36: 0 | J36: 1 | K36: 0-0-1 | L36: 1-0-1 | M36: 1-0-2 | N36: 1-0-2 | O36: 10 | P36: 11 | Q36: -1 | R36: L1 | S36: 1-0-2
A37: Edmonton Oilers | B37: 2 | C37: 1 | D37: 0 | E37: 1 | F37: 3 | G37: 1 | H37: 1 | I37: 0 | J37: 1 | K37: 1-0-1 | L37: 0-0-0 | M37: 1-0-1 | N37: 1-0-1 | O37: 6 | P37: 5 | Q37: 1 | R37: W1 | S37: 1-0-1
A38: Los Angeles Kings | B38: 4 | C38: 1 | D38: 2 | E38: 1 | F38: 3 | G38: 0 | H38: 0 | I38: 1 | J38: 1 | K38: 0-1-0 | L38: 1-1-1 | M38: 1-0-0 | N38: 1-2-1 | O38: 12 | P38: 16 | Q38: -4 | R38: L2 | S38: 1-2-1
A39: Anaheim Ducks | B39: 2 | C39: 1 | D39: 1 | E39: 0 | F39: 2 | G39: 0 | H39: 1 | I39: 0 | J39: 0 | K39: 0-0-0 | L39: 1-1-0 | M39: 1-1-0 | N39: 1-1-0 | O39: 8 | P39: 9 | Q39: -1 | R39: W1 | S39: 1-1-0
A40: Calgary Flames | B40: 3 | C40: 1 | D40: 2 | E40: 0 | F40: 2 | G40: 0 | H40: 0 | I40: 1 | J40: 0 | K40: 0-1-0 | L40: 1-1-0 | M40: 1-1-0 | N40: 1-2-0 | O40: 7 | P40: 12 | Q40: -5 | R40: L2 | S40: 1-2-0
...

Sheet Standings (10_14_25)
A1: Eastern Conference | T1: HOME
A2: Atlantic
A3: Team | B3: GP | C3: W | D3: L | E3: OTL | F3: PTS | G3: RW | H3: ROW | I3: SOW | J3: SOL | K3: Home | L3: Away | M3: Division | N3: Conference | O3: GF | P3: GA | Q3: Diff | R3: Strk | S3: L10
A4: Boston Bruins | B4: 4 | C4: 3 | D4: 1 | E4: 0 | F4: 6 | G4: 2 | H4: 3 | I4: 0 | J4: 0 | K4: 2-1-0 | L4: 1-0-0 | M4: 1-1-0 | N4: 2-1-0 | O4: 13 | P4: 9 | Q4: 4 | R4: L1 | S4: 3-1-0
A5: Florida Panthers | B5: 4 | C5: 3 | D5: 1 | E5: 0 | F5: 6 | G5: 3 | H5: 3 | I5: 0 | J5: 0 | K5: 3-0-0 | L5: 0-1-0 | M5: 1-0-0 | N5: 2-1-0 | O5: 13 | P5: 10 | Q5: 3 | R5: L1 | S5: 3-1-0
A6: Montreal Canadiens | B6: 4 | C6: 3 | D6: 1 | E6: 0 | F6: 6 | G6: 2 | H6: 3 | I6: 0 | J6: 0 | K6: 1-0-0 | L6: 2-1-0 | M6: 1-1-0 | N6: 1-1-0 | O6: 15 | P6: 12 | Q6: 3 | R6: W3 | S6: 3-1-0
A7: Detroit Red Wings | B7: 3 | C7: 2 | D7: 1 | E7: 0 | F7: 4 | G7: 2 | H7: 2 | I7: 0 | J7: 0 | K7: 1-1-0 | L7: 1-0-0 | M7: 2-1-0 | N7: 2-1-0 | O7: 10 | P7: 10 | Q7: 0 | R7: W2 | S7: 2-1-0
A8: Toronto Maple Leafs | B8: 4 | C8: 2 | D8: 2 | E8: 0 | F8: 4 | G8: 2 | H8: 2 | I8: 0 | J8: 0 | K8: 2-1-0 | L8: 0-1-0 | M8: 1-2-0 | N8: 1-2-0 | O8: 17 | P8: 15 | Q8: 2 | R8: W1 | S8: 2-2-0
A9: Tampa Bay Lightning | B9: 4 | C9: 1 | D9: 2 | E9: 1 | F9: 3 | G9: 1 | H9: 1 | I9: 0 | J9: 0 | K9: 0-2-0 | L9: 1-0-1 | M9: 1-1-0 | N9: 1-2-1 | O9: 13 | P9: 16 | Q9: -3 | R9: L1 | S9: 1-2-1
A10: Ottawa Senators | B10: 3 | C10: 1 | D10: 2 | E10: 0 | F10: 2 | G10: 1 | H10: 1 | I10: 0 | J10: 0 | K10: 0-1-0 | L10: 1-1-0 | M10: 1-1-0 | N10: 1-1-0 | O10: 8 | P10: 14 | Q10: -6 | R10: L2 | S10: 1-2-0
A11: Buffalo Sabres | B11: 3 | C11: 0 | D11: 3 | E11: 0 | F11: 0 | G11: 0 | H11: 0 | I11: 0 | J11: 0 | K11: 0-2-0 | L11: 0-1-0 | M11: 0-1-0 | N11: 0-2-0 | O11: 2 | P11: 10 | Q11: -8 | R11: L3 | S11: 0-3-0
A12: Metropolitan
A13: Team | B13: GP | C13: W | D13: L | E13: OTL | F13: PTS | G13: RW | H13: ROW | I13: SOW | J13: SOL | K13: Home | L13: Away | M13: Division | N13: Conference | O13: GF | P13: GA | Q13: Diff | R13: Strk | S13: L10
A14: Carolina Hurricanes | B14: 3 | C14: 3 | D14: 0 | E14: 0 | F14: 6 | G14: 2 | H14: 3 | I14: 0 | J14: 0 | K14: 2-0-0 | L14: 1-0-0 | M14: 2-0-0 | N14: 2-0-0 | O14: 15 | P14: 7 | Q14: 8 | R14: W3 | S14: 3-0-0
A15: Washington Capitals | B15: 4 | C15: 3 | D15: 1 | E15: 0 | F15: 6 | G15: 2 | H15: 3 | I15: 0 | J15: 0 | K15: 1-1-0 | L15: 2-0-0 | M15: 2-0-0 | N15: 3-1-0 | O15: 9 | P15: 7 | Q15: 2 | R15: W3 | S15: 3-1-0
A16: New Jersey Devils | B16: 3 | C16: 2 | D16: 1 | E16: 0 | F16: 4 | G16: 2 | H16: 2 | I16: 0 | J16: 0 | K16: 0-0-0 | L16: 2-1-0 | M16: 1-1-0 | N16: 2-1-0 | O16: 11 | P16: 11 | Q16: 0 | R16: W2 | S16: 2-1-0
A17: New York Rangers | B17: 5 | C17: 2 | D17: 3 | E17: 0 | F17: 4 | G17: 2 | H17: 2 | I17: 0 | J17: 0 | K17: 0-3-0 | L17: 2-0-0 | M17: 1-2-0 | N17: 2-2-0 | O17: 10 | P17: 7 | Q17: 3 | R17: L2 | S17: 2-3-0
A18: Pittsburgh Penguins | B18: 4 | C18: 2 | D18: 2 | E18: 0 | F18: 4 | G18: 2 | H18: 2 | I18: 0 | J18: 0 | K18: 1-1-0 | L18: 1-1-0 | M18: 2-1-0 | N18: 2-1-0 | O18: 11 | P18: 13 | Q18: -2 | R18: L2 | S18: 2-2-0
A19: Philadelphia Flyers | B19: 3 | C19: 1 | D19: 1 | E19: 1 | F19: 3 | G19: 1 | H19: 1 | I19: 0 | J19: 0 | K19: 1-0-0 | L19: 0-1-1 | M19: 0-0-1 | N19: 1-1-1 | O19: 9 | P19: 8 | Q19: 1 | R19: W1 | S19: 1-1-1
A20: Columbus Blue Jackets | B20: 3 | C20: 1 | D20: 2 | E20: 0 | F20: 2 | G20: 1 | H20: 1 | I20: 0 | J20: 0 | K20: 0-1-0 | L20: 1-1-0 | M20: 0-1-0 | N20: 0-1-0 | O20: 10 | P20: 9 | Q20: 1 | R20: L1 | S20: 1-2-0
A21: New York Islanders | B21: 3 | C21: 0 | D21: 3 | E21: 0 | F21: 0 | G21: 0 | H21: 0 | I21: 0 | J21: 0 | K21: 0-2-0 | L21: 0-1-0 | M21: 0-2-0 | N21: 0-2-0 | O21: 7 | P21: 13 | Q21: -6 | R21: L3 | S21: 0-3-0
A22: Western_Conference
A23: Central
A24: Team | B24: GP | C24: W | D24: L | E24: OTL | F24: PTS | G24: RW | H24: ROW | I24: SOW | J24: SOL | K24: Home | L24: Away | M24: Division | N24: Conference | O24: GF | P24: GA | Q24: Diff | R24: Strk | S24: L10
A25: Colorado Avalanche | B25: 4 | C25: 3 | D25: 0 | E25: 1 | F25: 7 | G25: 3 | H25: 3 | I25: 0 | J25: 1 | K25: 1-0-1 | L25: 2-0-0 | M25: 1-0-1 | N25: 2-0-1 | O25: 13 | P25: 8 | Q25: 5 | R25: W1 | S25: 3-0-1
A26: Dallas Stars | B26: 3 | C26: 3 | D26: 0 | E26: 0 | F26: 6 | G26: 1 | H26: 2 | I26: 1 | J26: 0 | K26: 1-0-0 | L26: 2-0-0 | M26: 3-0-0 | N26: 3-0-0 | O26: 15 | P26: 10 | Q26: 5 | R26: W3 | S26: 3-0-0
A27: Nashville Predators | B27: 4 | C27: 2 | D27: 1 | E27: 1 | F27: 5 | G27: 2 | H27: 2 | I27: 0 | J27: 0 | K27: 1-0-1 | L27: 1-1-0 | M27: 0-0-1 | N27: 0-0-1 | O27: 12 | P27: 12 | Q27: 0 | R27: L1 | S27: 2-1-1
A28: Minnesota Wild | B28: 4 | C28: 2 | D28: 2 | E28: 0 | F28: 4 | G28: 1 | H28: 1 | I28: 1 | J28: 0 | K28: 1-1-0 | L28: 1-1-0 | M28: 1-1-0 | N28: 2-1-0 | O28: 15 | P28: 15 | Q28: 0 | R28: L1 | S28: 2-2-0
A29: St. Louis Blues | B29: 3 | C29: 2 | D29: 1 | E29: 0 | F29: 4 | G29: 2 | H29: 2 | I29: 0 | J29: 0 | K29: 0-1-0 | L29: 2-0-0 | M29: 0-1-0 | N29: 2-1-0 | O29: 9 | P29: 9 | Q29: 0 | R29: W2 | S29: 2-1-0
A30: Winnipeg Jets | B30: 3 | C30: 2 | D30: 1 | E30: 0 | F30: 4 | G30: 2 | H30: 2 | I30: 0 | J30: 0 | K30: 1-1-0 | L30: 1-0-0 | M30: 0-1-0 | N30: 1-1-0 | O30: 12 | P30: 9 | Q30: 3 | R30: W2 | S30: 2-1-0
A31: Chicago Blackhawks | B31: 4 | C31: 1 | D31: 2 | E31: 1 | F31: 3 | G31: 1 | H31: 1 | I31: 0 | J31: 0 | K31: 1-1-0 | L31: 0-1-1 | M31: 1-0-0 | N31: 1-0-0 | O31: 10 | P31: 11 | Q31: -1 | R31: W1 | S31: 1-2-1
A32: Utah Mammoth | B32: 3 | C32: 1 | D32: 2 | E32: 0 | F32: 2 | G32: 0 | H32: 1 | I32: 0 | J32: 0 | K32: 0-0-0 | L32: 1-2-0 | M32: 1-2-0 | N32: 1-2-0 | O32: 5 | P32: 7 | Q32: -2 | R32: L1 | S32: 1-2-0
A33: Pacific
A34: Team | B34: GP | C34: W | D34: L | E34: OTL | F34: PTS | G34: RW | H34: ROW | I34: SOW | J34: SOL | K34: Home | L34: Away | M34: Division | N34: Conference | O34: GF | P34: GA | Q34: Diff | R34: Strk | S34: L10
A35: Vegas Golden Knights | B35: 4 | C35: 2 | D35: 0 | E35: 2 | F35: 6 | G35: 1 | H35: 2 | I35: 0 | J35: 1 | K35: 0-0-1 | L35: 2-0-1 | M35: 2-0-2 | N35: 2-0-2 | O35: 14 | P35: 13 | Q35: 1 | R35: W1 | S35: 2-0-2
A36: Edmonton Oilers | B36: 3 | C36: 2 | D36: 0 | E36: 1 | F36: 5 | G36: 2 | H36: 2 | I36: 0 | J36: 1 | K36: 1-0-1 | L36: 1-0-0 | M36: 1-0-1 | N36: 1-0-1 | O36: 8 | P36: 5 | Q36: 3 | R36: W2 | S36: 2-0-1
A37: Seattle Kraken | B37: 3 | C37: 2 | D37: 0 | E37: 1 | F37: 5 | G37: 1 | H37: 2 | I37: 0 | J37: 0 | K37: 2-0-0 | L37: 0-0-1 | M37: 2-0-0 | N37: 2-0-0 | O37: 9 | P37: 7 | Q37: 2 | R37: L1 | S37: 2-0-1
A38: Anaheim Ducks | B38: 3 | C38: 2 | D38: 1 | E38: 0 | F38: 4 | G38: 1 | H38: 2 | I38: 0 | J38: 0 | K38: 1-0-0 | L38: 1-1-0 | M38: 1-1-0 | N38: 1-1-0 | O38: 12 | P38: 12 | Q38: 0 | R38: W2 | S38: 2-1-0
A39: Los Angeles Kings | B39: 4 | C39: 1 | D39: 2 | E39: 1 | F39: 3 | G39: 0 | H39: 0 | I39: 1 | J39: 1 | K39: 0-1-0 | L39: 1-1-1 | M39: 1-0-0 | N39: 1-2-1 | O39: 12 | P39: 16 | Q39: -4 | R39: L2 | S39: 1-2-1
A40: Calgary Flames | B40: 4 | C40: 1 | D40: 3 | E40: 0 | F40: 2 | G40: 0 | H40: 0 | I40: 1 | J40: 0 | K40: 0-2-0 | L40: 1-1-0 | M40: 1-2-0 | N40: 1-3-0 | O40: 9 | P40: 16 | Q40: -7 | R40: L3 | S40: 1-3-0
...

Sheet Standings (10_15_25)
A1: Eastern Conference | T1: HOME
A2: Atlantic
A3: Team | B3: GP | C3: W | D3: L | E3: OTL | F3: PTS | G3: RW | H3: ROW | I3: SOW | J3: SOL | K3: Home | L3: Away | M3: Division | N3: Conference | O3: GF | P3: GA | Q3: Diff | R3: Strk | S3: L10
A4: Boston Bruins | B4: 4 | C4: 3 | D4: 1 | E4: 0 | F4: 6 | G4: 2 | H4: 3 | I4: 0 | J4: 0 | K4: 2-1-0 | L4: 1-0-0 | M4: 1-1-0 | N4: 2-1-0 | O4: 13 | P4: 9 | Q4: 4 | R4: L1 | S4: 3-1-0
A5: Detroit Red Wings | B5: 4 | C5: 3 | D5: 1 | E5: 0 | F5: 6 | G5: 3 | H5: 3 | I5: 0 | J5: 0 | K5: 2-1-0 | L5: 1-0-0 | M5: 3-1-0 | N5: 3-1-0 | O5: 14 | P5: 11 | Q5: 3 | R5: W3 | S5: 3-1-0
A6: Florida Panthers | B6: 5 | C6: 3 | D6: 2 | E6: 0 | F6: 6 | G6: 3 | H6: 3 | I6: 0 | J6: 0 | K6: 3-0-0 | L6: 0-2-0 | M6: 1-1-0 | N6: 2-2-0 | O6: 14 | P6: 14 | Q6: 0 | R6: L2 | S6: 3-2-0
A7: Montreal Canadiens | B7: 4 | C7: 3 | D7: 1 | E7: 0 | F7: 6 | G7: 2 | H7: 3 | I7: 0 | J7: 0 | K7: 1-0-0 | L7: 2-1-0 | M7: 1-1-0 | N7: 1-1-0 | O7: 15 | P7: 12 | Q7: 3 | R7: W3 | S7: 3-1-0
A8: Toronto Maple Leafs | B8: 4 | C8: 2 | D8: 2 | E8: 0 | F8: 4 | G8: 2 | H8: 2 | I8: 0 | J8: 0 | K8: 2-1-0 | L8: 0-1-0 | M8: 1-2-0 | N8: 1-2-0 | O8: 17 | P8: 15 | Q8: 2 | R8: W1 | S8: 2-2-0
A9: Tampa Bay Lightning | B9: 4 | C9: 1 | D9: 2 | E9: 1 | F9: 3 | G9: 1 | H9: 1 | I9: 0 | J9: 0 | K9: 0-2-0 | L9: 1-0-1 | M9: 1-1-0 | N9: 1-2-1 | O9: 13 | P9: 16 | Q9: -3 | R9: L1 | S9: 1-2-1
A10: Buffalo Sabres | B10: 4 | C10: 1 | D10: 3 | E10: 0 | F10: 2 | G10: 1 | H10: 1 | I10: 0 | J10: 0 | K10: 1-2-0 | L10: 0-1-0 | M10: 1-1-0 | N10: 1-2-0 | O10: 10 | P10: 14 | Q10: -4 | R10: W1 | S10: 1-3-0
A11: Ottawa Senators | B11: 4 | C11: 1 | D11: 3 | E11: 0 | F11: 2 | G11: 1 | H11: 1 | I11: 0 | J11: 0 | K11: 0-1-0 | L11: 1-2-0 | M11: 1-2-0 | N11: 1-2-0 | O11: 12 | P11: 22 | Q11: -10 | R11: L3 | S11: 1-3-0
A12: Metropolitan
A13: Team | B13: GP | C13: W | D13: L | E13: OTL | F13: PTS | G13: RW | H13: ROW | I13: SOW | J13: SOL | K13: Home | L13: Away | M13: Division | N13: Conference | O13: GF | P13: GA | Q13: Diff | R13: Strk | S13: L10
A14: Carolina Hurricanes | B14: 3 | C14: 3 | D14: 0 | E14: 0 | F14: 6 | G14: 2 | H14: 3 | I14: 0 | J14: 0 | K14: 2-0-0 | L14: 1-0-0 | M14: 2-0-0 | N14: 2-0-0 | O14: 15 | P14: 7 | Q14: 8 | R14: W3 | S14: 3-0-0
A15: Washington Capitals | B15: 4 | C15: 3 | D15: 1 | E15: 0 | F15: 6 | G15: 2 | H15: 3 | I15: 0 | J15: 0 | K15: 1-1-0 | L15: 2-0-0 | M15: 2-0-0 | N15: 3-1-0 | O15: 9 | P15: 7 | Q15: 2 | R15: W3 | S15: 3-1-0
A16: New Jersey Devils | B16: 3 | C16: 2 | D16: 1 | E16: 0 | F16: 4 | G16: 2 | H16: 2 | I16: 0 | J16: 0 | K16: 0-0-0 | L16: 2-1-0 | M16: 1-1-0 | N16: 2-1-0 | O16: 11 | P16: 11 | Q16: 0 | R16: W2 | S16: 2-1-0
A17: New York Rangers | B17: 5 | C17: 2 | D17: 3 | E17: 0 | F17: 4 | G17: 2 | H17: 2 | I17: 0 | J17: 0 | K17: 0-3-0 | L17: 2-0-0 | M17: 1-2-0 | N17: 2-2-0 | O17: 10 | P17: 7 | Q17: 3 | R17: L2 | S17: 2-3-0
A18: Pittsburgh Penguins | B18: 4 | C18: 2 | D18: 2 | E18: 0 | F18: 4 | G18: 2 | H18: 2 | I18: 0 | J18: 0 | K18: 1-1-0 | L18: 1-1-0 | M18: 2-1-0 | N18: 2-1-0 | O18: 11 | P18: 13 | Q18: -2 | R18: L2 | S18: 2-2-0
A19: Philadelphia Flyers | B19: 3 | C19: 1 | D19: 1 | E19: 1 | F19: 3 | G19: 1 | H19: 1 | I19: 0 | J19: 0 | K19: 1-0-0 | L19: 0-1-1 | M19: 0-0-1 | N19: 1-1-1 | O19: 9 | P19: 8 | Q19: 1 | R19: W1 | S19: 1-1-1
A20: Columbus Blue Jackets | B20: 3 | C20: 1 | D20: 2 | E20: 0 | F20: 2 | G20: 1 | H20: 1 | I20: 0 | J20: 0 | K20: 0-1-0 | L20: 1-1-0 | M20: 0-1-0 | N20: 0-1-0 | O20: 10 | P20: 9 | Q20: 1 | R20: L1 | S20: 1-2-0
A21: New York Islanders | B21: 3 | C21: 0 | D21: 3 | E21: 0 | F21: 0 | G21: 0 | H21: 0 | I21: 0 | J21: 0 | K21: 0-2-0 | L21: 0-1-0 | M21: 0-2-0 | N21: 0-2-0 | O21: 7 | P21: 13 | Q21: -6 | R21: L3 | S21: 0-3-0
A22: Western_Conference
A23: Central
A24: Team | B24: GP | C24: W | D24: L | E24: OTL | F24: PTS | G24: RW | H24: ROW | I24: SOW | J24: SOL | K24: Home | L24: Away | M24: Division | N24: Conference | O24: GF | P24: GA | Q24: Diff | R24: Strk | S24: L10
A25: Colorado Avalanche | B25: 4 | C25: 3 | D25: 0 | E25: 1 | F25: 7 | G25: 3 | H25: 3 | I25: 0 | J25: 1 | K25: 1-0-1 | L25: 2-0-0 | M25: 1-0-1 | N25: 2-0-1 | O25: 13 | P25: 8 | Q25: 5 | R25: W1 | S25: 3-0-1
A26: Dallas Stars | B26: 3 | C26: 3 | D26: 0 | E26: 0 | F26: 6 | G26: 1 | H26: 2 | I26: 1 | J26: 0 | K26: 1-0-0 | L26: 2-0-0 | M26: 3-0-0 | N26: 3-0-0 | O26: 15 | P26: 10 | Q26: 5 | R26: W3 | S26: 3-0-0
A27: Chicago Blackhawks | B27: 5 | C27: 2 | D27: 2 | E27: 1 | F27: 5 | G27: 2 | H27: 2 | I27: 0 | J27: 0 | K27: 1-1-0 | L27: 1-1-1 | M27: 2-0-0 | N27: 2-0-0 | O27: 18 | P27: 14 | Q27: 4 | R27: W2 | S27: 2-2-1
A28: Nashville Predators | B28: 4 | C28: 2 | D28: 1 | E28: 1 | F28: 5 | G28: 2 | H28: 2 | I28: 0 | J28: 0 | K28: 1-0-1 | L28: 1-1-0 | M28: 0-0-1 | N28: 0-0-1 | O28: 12 | P28: 12 | Q28: 0 | R28: L1 | S28: 2-1-1
A29: Minnesota Wild | B29: 4 | C29: 2 | D29: 2 | E29: 0 | F29: 4 | G29: 1 | H29: 1 | I29: 1 | J29: 0 | K29: 1-1-0 | L29: 1-1-0 | M29: 1-1-0 | N29: 2-1-0 | O29: 15 | P29: 15 | Q29: 0 | R29: L1 | S29: 2-2-0
A30: St. Louis Blues | B30: 4 | C30: 2 | D30: 2 | E30: 0 | F30: 4 | G30: 2 | H30: 2 | I30: 0 | J30: 0 | K30: 0-2-0 | L30: 2-0-0 | M30: 0-2-0 | N30: 2-2-0 | O30: 12 | P30: 17 | Q30: -5 | R30: L1 | S30: 2-2-0
A31: Utah Mammoth | B31: 4 | C31: 2 | D31: 2 | E31: 0 | F31: 4 | G31: 1 | H31: 2 | I31: 0 | J31: 0 | K31: 1-0-0 | L31: 1-2-0 | M31: 1-2-0 | N31: 2-2-0 | O31: 8 | P31: 8 | Q31: 0 | R31: W1 | S31: 2-2-0
A32: Winnipeg Jets | B32: 3 | C32: 2 | D32: 1 | E32: 0 | F32: 4 | G32: 2 | H32: 2 | I32: 0 | J32: 0 | K32: 1-1-0 | L32: 1-0-0 | M32: 0-1-0 | N32: 1-1-0 | O32: 12 | P32: 9 | Q32: 3 | R32: W2 | S32: 2-1-0
A33: Pacific
A34: Team | B34: GP | C34: W | D34: L | E34: OTL | F34: PTS | G34: RW | H34: ROW | I34: SOW | J34: SOL | K34: Home | L34: Away | M34: Division | N34: Conference | O34: GF | P34: GA | Q34: Diff | R34: Strk | S34: L10
A35: Vegas Golden Knights | B35: 4 | C35: 2 | D35: 0 | E35: 2 | F35: 6 | G35: 1 | H35: 2 | I35: 0 | J35: 1 | K35: 0-0-1 | L35: 2-0-1 | M35: 2-0-2 | N35: 2-0-2 | O35: 14 | P35: 13 | Q35: 1 | R35: W1 | S35: 2-0-2
A36: Edmonton Oilers | B36: 3 | C36: 2 | D36: 0 | E36: 1 | F36: 5 | G36: 2 | H36: 2 | I36: 0 | J36: 1 | K36: 1-0-1 | L36: 1-0-0 | M36: 1-0-1 | N36: 1-0-1 | O36: 8 | P36: 5 | Q36: 3 | R36: W2 | S36: 2-0-1
A37: Seattle Kraken | B37: 3 | C37: 2 | D37: 0 | E37: 1 | F37: 5 | G37: 1 | H37: 2 | I37: 0 | J37: 0 | K37: 2-0-0 | L37: 0-0-1 | M37: 2-0-0 | N37: 2-0-0 | O37: 9 | P37: 7 | Q37: 2 | R37: L1 | S37: 2-0-1
A38: Anaheim Ducks | B38: 3 | C38: 2 | D38: 1 | E38: 0 | F38: 4 | G38: 1 | H38: 2 | I38: 0 | J38: 0 | K38: 1-0-0 | L38: 1-1-0 | M38: 1-1-0 | N38: 1-1-0 | O38: 12 | P38: 12 | Q38: 0 | R38: W2 | S38: 2-1-0
A39: Los Angeles Kings | B39: 4 | C39: 1 | D39: 2 | E39: 1 | F39: 3 | G39: 0 | H39: 0 | I39: 1 | J39: 1 | K39: 0-1-0 | L39: 1-1-1 | M39: 1-0-0 | N39: 1-2-1 | O39: 12 | P39: 16 | Q39: -4 | R39: L2 | S39: 1-2-1
A40: Calgary Flames | B40: 5 | C40: 1 | D40: 4 | E40: 0 | F40: 2 | G40: 0 | H40: 0 | I40: 1 | J40: 0 | K40: 0-2-0 | L40: 1-2-0 | M40: 1-2-0 | N40: 1-4-0 | O40: 10 | P40: 19 | Q40: -9 | R40: L4 | S40: 1-4-0
...

Sheet Standings (10_16_25)
